2019-12-10 15:48:29,916  * Running on http://127.0.0.1:5000/ (Press CTRL+C to quit)
2019-12-10 15:48:49,189  * Running on http://127.0.0.1:5000/ (Press CTRL+C to quit)
2019-12-10 15:49:13,271 Exception on /submit [GET]
Traceback (most recent call last):
  File "/Library/Frameworks/Python.framework/Versions/3.7/lib/python3.7/site-packages/flask/app.py", line 2446, in wsgi_app
    response = self.full_dispatch_request()
  File "/Library/Frameworks/Python.framework/Versions/3.7/lib/python3.7/site-packages/flask/app.py", line 1952, in full_dispatch_request
    return self.finalize_request(rv)
  File "/Library/Frameworks/Python.framework/Versions/3.7/lib/python3.7/site-packages/flask/app.py", line 1967, in finalize_request
    response = self.make_response(rv)
  File "/Library/Frameworks/Python.framework/Versions/3.7/lib/python3.7/site-packages/flask/app.py", line 2130, in make_response
    " {rv.__class__.__name__}.".format(rv=rv)
TypeError: The view function did not return a valid response. The return type must be a string, dict, tuple, Response instance, or WSGI callable, but it was a int.
2019-12-10 15:49:13,274 127.0.0.1 - - [10/Dec/2019 15:49:13] "GET /submit?url=https://sun9-69.userapi.com/c824201/v824201969/17341f/IfCwbiGRL7c.jpg HTTP/1.1" 500 -
2019-12-10 15:50:59,411  * Running on http://127.0.0.1:5000/ (Press CTRL+C to quit)
2019-12-10 15:56:18,482  * Running on http://127.0.0.1:5000/ (Press CTRL+C to quit)
2019-12-10 15:57:10,656  * Running on http://127.0.0.1:5000/ (Press CTRL+C to quit)
2019-12-12 17:11:57,192  * Running on http://127.0.0.1:5000/ (Press CTRL+C to quit)
2019-12-12 17:12:18,928 poehali
2019-12-12 17:12:19,050 127.0.0.1 - - [12/Dec/2019 17:12:19] "GET /submit?url=https://sun9-69.userapi.com/c824201/v824201969/17341f/IfCwbiGRL7c.jpg%22%27 HTTP/1.1" 200 -
2019-12-12 17:12:39,261  * Running on http://127.0.0.1:5000/ (Press CTRL+C to quit)
2019-12-12 17:12:59,184 poehali
2019-12-12 17:12:59,322 127.0.0.1 - - [12/Dec/2019 17:12:59] "GET /submit?url=https://sun9-69.userapi.com/c824201/v824201969/17341f/IfCwbiGRL7c.jpg%22%27 HTTP/1.1" 200 -
2019-12-12 17:13:41,190  * Running on http://127.0.0.1:5000/ (Press CTRL+C to quit)
2019-12-12 17:13:45,362 poehali
2019-12-12 17:13:45,425 calc_hash_sum
2019-12-12 17:13:45,426 127.0.0.1 - - [12/Dec/2019 17:13:45] "GET /submit?url=https://sun9-69.userapi.com/c824201/v824201969/17341f/IfCwbiGRL7c.jpg%22%27 HTTP/1.1" 200 -
2019-12-12 17:14:28,760  * Running on http://127.0.0.1:5000/ (Press CTRL+C to quit)
2019-12-12 17:14:32,247 poehali
2019-12-12 17:14:32,335 e36bd7f8-4ff1-4ad0-921a-570db5f22cb5
2019-12-12 17:14:32,336 127.0.0.1 - - [12/Dec/2019 17:14:32] "GET /submit?url=https://sun9-69.userapi.com/c824201/v824201969/17341f/IfCwbiGRL7c.jpg%22%27 HTTP/1.1" 200 -
2019-12-12 17:15:08,358  * Running on http://127.0.0.1:5000/ (Press CTRL+C to quit)
2019-12-12 17:15:11,167 poehali
2019-12-12 17:15:11,258 2517e95a-ae72-4a65-bb27-a1ccbaf2f55b
2019-12-12 17:15:11,259 127.0.0.1 - - [12/Dec/2019 17:15:11] "GET /submit?url=https://sun9-69.userapi.com/c824201/v824201969/17341f/IfCwbiGRL7c.jpg%22%27 HTTP/1.1" 200 -
2019-12-12 17:16:24,718  * Running on http://127.0.0.1:5000/ (Press CTRL+C to quit)
2019-12-12 17:16:26,659 poehali
2019-12-12 17:16:26,745 b68d45c7-cf49-4ca3-b35d-2949d1165769
2019-12-12 17:16:26,745 127.0.0.1 - - [12/Dec/2019 17:16:26] "GET /submit?url=https://sun9-69.userapi.com/c824201/v824201969/17341f/IfCwbiGRL7c.jpg%22%27 HTTP/1.1" 200 -
2019-12-12 17:32:54,540  * Running on http://127.0.0.1:5000/ (Press CTRL+C to quit)
2019-12-12 17:32:59,297 127.0.0.1 - - [12/Dec/2019 17:32:59] "GET /submit?url=https://sun9-69.userapi.com/c824201/v824201969/17341f/IfCwbiGRL7c.jpg%22%27 HTTP/1.1" 200 -
2019-12-12 17:44:33,378  * Running on http://127.0.0.1:5000/ (Press CTRL+C to quit)
2019-12-12 17:44:38,671 127.0.0.1 - - [12/Dec/2019 17:44:38] "GET /submit?url=https://sun9-69.userapi.com/c824201/v824201969/17341f/IfCwbiGRL7c.jpg%22%27 HTTP/1.1" 200 -
2019-12-12 18:11:38,736  * Running on http://127.0.0.1:5000/ (Press CTRL+C to quit)
2019-12-12 18:11:46,574 127.0.0.1 - - [12/Dec/2019 18:11:46] "GET /submit?url=https://sun9-69.userapi.com/c824201/v824201969/17341f/IfCwbiGRL7c.jpg%22%27 HTTP/1.1" 200 -
2019-12-12 23:35:42,633  * Running on http://127.0.0.1:5000/ (Press CTRL+C to quit)
2019-12-12 23:35:48,576 127.0.0.1 - - [12/Dec/2019 23:35:48] "GET /submit?url=https://sun9-69.userapi.com/c824201/v824201969/17341f/IfCwbiGRL7c.jpg%22%27 HTTP/1.1" 200 -
2019-12-12 23:37:07,610  * Running on http://127.0.0.1:5000/ (Press CTRL+C to quit)
2019-12-12 23:37:10,193 127.0.0.1 - - [12/Dec/2019 23:37:10] "GET /submit?url=https://sun9-69.userapi.com/c824201/v824201969/17341f/IfCwbiGRL7c.jpg%22%27 HTTP/1.1" 200 -
2019-12-12 23:38:46,956  * Running on http://127.0.0.1:5000/ (Press CTRL+C to quit)
2019-12-12 23:38:50,138 127.0.0.1 - - [12/Dec/2019 23:38:50] "GET /submit?url=https://sun9-69.userapi.com/c824201/v824201969/17341f/IfCwbiGRL7c.jpg%22%27 HTTP/1.1" 200 -
2019-12-13 00:08:50,443  * Running on http://127.0.0.1:5000/ (Press CTRL+C to quit)
2019-12-13 00:09:00,987 127.0.0.1 - - [13/Dec/2019 00:09:00] "GET /submit?url=https://sun9-69.userapi.com/c824201/v824201969/17341f/IfCwbiGRL7c.jpg%22%27 HTTP/1.1" 200 -
2019-12-13 00:10:19,081  * Running on http://127.0.0.1:5000/ (Press CTRL+C to quit)
2019-12-13 00:10:21,557 127.0.0.1 - - [13/Dec/2019 00:10:21] "GET /submit?url=https://sun9-69.userapi.com/c824201/v824201969/17341f/IfCwbiGRL7c.jpg%22%27 HTTP/1.1" 200 -
2019-12-13 00:13:38,146  * Running on http://127.0.0.1:5000/ (Press CTRL+C to quit)
2019-12-13 00:13:43,496 127.0.0.1 - - [13/Dec/2019 00:13:43] "GET /submit?url=https://sun9-69.userapi.com/c824201/v824201969/17341f/IfCwbiGRL7c.jpg%22%27 HTTP/1.1" 200 -
2019-12-13 00:18:01,050  * Running on http://127.0.0.1:5000/ (Press CTRL+C to quit)
2019-12-13 00:18:07,715 Exception on /submit [GET]
Traceback (most recent call last):
  File "/Library/Frameworks/Python.framework/Versions/3.7/lib/python3.7/site-packages/flask/app.py", line 2446, in wsgi_app
    response = self.full_dispatch_request()
  File "/Library/Frameworks/Python.framework/Versions/3.7/lib/python3.7/site-packages/flask/app.py", line 1951, in full_dispatch_request
    rv = self.handle_user_exception(e)
  File "/Library/Frameworks/Python.framework/Versions/3.7/lib/python3.7/site-packages/flask/app.py", line 1820, in handle_user_exception
    reraise(exc_type, exc_value, tb)
  File "/Library/Frameworks/Python.framework/Versions/3.7/lib/python3.7/site-packages/flask/_compat.py", line 39, in reraise
    raise value
  File "/Library/Frameworks/Python.framework/Versions/3.7/lib/python3.7/site-packages/flask/app.py", line 1949, in full_dispatch_request
    rv = self.dispatch_request()
  File "/Library/Frameworks/Python.framework/Versions/3.7/lib/python3.7/site-packages/flask/app.py", line 1935, in dispatch_request
    return self.view_functions[rule.endpoint](**req.view_args)
  File "/Users/sergeykostitsin/MD5_service/server/flaskserv.py", line 42, in post
    task_id = create_task_with_id(url,email)
  File "/Users/sergeykostitsin/MD5_service/server/flaskserv.py", line 48, in create_task_with_id
    task = calc_hash_sum.apply_async(url,mail)
  File "/Library/Frameworks/Python.framework/Versions/3.7/lib/python3.7/site-packages/celery/app/task.py", line 532, in apply_async
    check_arguments(*(args or ()), **(kwargs or {}))
TypeError: calc_hash_sum() argument after ** must be a mapping, not str
2019-12-13 00:18:07,721 127.0.0.1 - - [13/Dec/2019 00:18:07] "GET /submit?url=https://sun9-69.userapi.com/c824201/v824201969/17341f/IfCwbiGRL7c.jpg%22%27 HTTP/1.1" 500 -
2019-12-13 00:19:00,453  * Running on http://127.0.0.1:5000/ (Press CTRL+C to quit)
2019-12-13 00:19:14,947 127.0.0.1 - - [13/Dec/2019 00:19:14] "GET /submit?url=https://sun9-69.userapi.com/c824201/v824201969/17341f/IfCwbiGRL7c.jpg%22%27 HTTP/1.1" 200 -
2019-12-13 00:40:48,764  * Running on http://127.0.0.1:5000/ (Press CTRL+C to quit)
2019-12-13 00:41:05,067 127.0.0.1 - - [13/Dec/2019 00:41:05] "GET /submit?url=https://sun9-69.userapi.com/c824201/v824201969/17341f/IfCwbiGRL7c.jpg%22%27 HTTP/1.1" 200 -
2019-12-13 00:43:28,221  * Running on http://127.0.0.1:5000/ (Press CTRL+C to quit)
2019-12-13 00:45:55,627  * Running on http://127.0.0.1:5000/ (Press CTRL+C to quit)
2019-12-13 00:46:03,352 127.0.0.1 - - [13/Dec/2019 00:46:03] "GET /submit?url=https://sun9-69.userapi.com/c824201/v824201969/17341f/IfCwbiGRL7c.jpg%22%27 HTTP/1.1" 200 -
2019-12-13 00:50:06,888  * Running on http://127.0.0.1:5000/ (Press CTRL+C to quit)
2019-12-13 00:50:18,274 Exception on /submit [GET]
Traceback (most recent call last):
  File "/Library/Frameworks/Python.framework/Versions/3.7/lib/python3.7/site-packages/flask/app.py", line 2446, in wsgi_app
    response = self.full_dispatch_request()
  File "/Library/Frameworks/Python.framework/Versions/3.7/lib/python3.7/site-packages/flask/app.py", line 1951, in full_dispatch_request
    rv = self.handle_user_exception(e)
  File "/Library/Frameworks/Python.framework/Versions/3.7/lib/python3.7/site-packages/flask/app.py", line 1820, in handle_user_exception
    reraise(exc_type, exc_value, tb)
  File "/Library/Frameworks/Python.framework/Versions/3.7/lib/python3.7/site-packages/flask/_compat.py", line 39, in reraise
    raise value
  File "/Library/Frameworks/Python.framework/Versions/3.7/lib/python3.7/site-packages/flask/app.py", line 1949, in full_dispatch_request
    rv = self.dispatch_request()
  File "/Library/Frameworks/Python.framework/Versions/3.7/lib/python3.7/site-packages/flask/app.py", line 1935, in dispatch_request
    return self.view_functions[rule.endpoint](**req.view_args)
  File "/Users/sergeykostitsin/MD5_service/server/flaskserv.py", line 44, in post
    task_id = create_task_with_id(url,email)
  File "/Users/sergeykostitsin/MD5_service/server/flaskserv.py", line 50, in create_task_with_id
    task = calc_hash_sum(url,mail)
  File "/Library/Frameworks/Python.framework/Versions/3.7/lib/python3.7/site-packages/celery/local.py", line 191, in __call__
    return self._get_current_object()(*a, **kw)
  File "/Library/Frameworks/Python.framework/Versions/3.7/lib/python3.7/site-packages/celery/app/task.py", line 394, in __call__
    return self.run(*args, **kwargs)
  File "/Users/sergeykostitsin/MD5_service/server/flaskserv.py", line 55, in calc_hash_sum
    file = requests.get(url)
  File "/Library/Frameworks/Python.framework/Versions/3.7/lib/python3.7/site-packages/requests/api.py", line 75, in get
    return request('get', url, params=params, **kwargs)
  File "/Library/Frameworks/Python.framework/Versions/3.7/lib/python3.7/site-packages/requests/api.py", line 60, in request
    return session.request(method=method, url=url, **kwargs)
  File "/Library/Frameworks/Python.framework/Versions/3.7/lib/python3.7/site-packages/requests/sessions.py", line 519, in request
    prep = self.prepare_request(req)
  File "/Library/Frameworks/Python.framework/Versions/3.7/lib/python3.7/site-packages/requests/sessions.py", line 462, in prepare_request
    hooks=merge_hooks(request.hooks, self.hooks),
  File "/Library/Frameworks/Python.framework/Versions/3.7/lib/python3.7/site-packages/requests/models.py", line 313, in prepare
    self.prepare_url(url, params)
  File "/Library/Frameworks/Python.framework/Versions/3.7/lib/python3.7/site-packages/requests/models.py", line 387, in prepare_url
    raise MissingSchema(error)
requests.exceptions.MissingSchema: Invalid URL 'None': No schema supplied. Perhaps you meant http://None?
2019-12-13 00:50:18,280 127.0.0.1 - - [13/Dec/2019 00:50:18] "GET /submit?url=https://sun9-69.userapi.com/c824201/v824201969/17341f/IfCwbiGRL7c.jpg%22%27 HTTP/1.1" 500 -
2019-12-13 00:51:18,949  * Running on http://127.0.0.1:5000/ (Press CTRL+C to quit)
2019-12-13 00:51:39,299  * Running on http://127.0.0.1:5000/ (Press CTRL+C to quit)
2019-12-13 00:52:18,105  * Running on http://127.0.0.1:5000/ (Press CTRL+C to quit)
2019-12-13 00:52:27,815 Exception on /submit [GET]
Traceback (most recent call last):
  File "/Library/Frameworks/Python.framework/Versions/3.7/lib/python3.7/site-packages/flask/app.py", line 2446, in wsgi_app
    response = self.full_dispatch_request()
  File "/Library/Frameworks/Python.framework/Versions/3.7/lib/python3.7/site-packages/flask/app.py", line 1951, in full_dispatch_request
    rv = self.handle_user_exception(e)
  File "/Library/Frameworks/Python.framework/Versions/3.7/lib/python3.7/site-packages/flask/app.py", line 1820, in handle_user_exception
    reraise(exc_type, exc_value, tb)
  File "/Library/Frameworks/Python.framework/Versions/3.7/lib/python3.7/site-packages/flask/_compat.py", line 39, in reraise
    raise value
  File "/Library/Frameworks/Python.framework/Versions/3.7/lib/python3.7/site-packages/flask/app.py", line 1949, in full_dispatch_request
    rv = self.dispatch_request()
  File "/Library/Frameworks/Python.framework/Versions/3.7/lib/python3.7/site-packages/flask/app.py", line 1935, in dispatch_request
    return self.view_functions[rule.endpoint](**req.view_args)
  File "/Users/sergeykostitsin/MD5_service/server/flaskserv.py", line 44, in post
    task_id = create_task_with_id(url,email)
  File "/Users/sergeykostitsin/MD5_service/server/flaskserv.py", line 50, in create_task_with_id
    task = calc_hash_sum(url,mail)
  File "/Users/sergeykostitsin/MD5_service/server/flaskserv.py", line 55, in calc_hash_sum
    file = requests.get(url)
  File "/Library/Frameworks/Python.framework/Versions/3.7/lib/python3.7/site-packages/requests/api.py", line 75, in get
    return request('get', url, params=params, **kwargs)
  File "/Library/Frameworks/Python.framework/Versions/3.7/lib/python3.7/site-packages/requests/api.py", line 60, in request
    return session.request(method=method, url=url, **kwargs)
  File "/Library/Frameworks/Python.framework/Versions/3.7/lib/python3.7/site-packages/requests/sessions.py", line 519, in request
    prep = self.prepare_request(req)
  File "/Library/Frameworks/Python.framework/Versions/3.7/lib/python3.7/site-packages/requests/sessions.py", line 462, in prepare_request
    hooks=merge_hooks(request.hooks, self.hooks),
  File "/Library/Frameworks/Python.framework/Versions/3.7/lib/python3.7/site-packages/requests/models.py", line 313, in prepare
    self.prepare_url(url, params)
  File "/Library/Frameworks/Python.framework/Versions/3.7/lib/python3.7/site-packages/requests/models.py", line 387, in prepare_url
    raise MissingSchema(error)
requests.exceptions.MissingSchema: Invalid URL 'None': No schema supplied. Perhaps you meant http://None?
2019-12-13 00:52:27,820 127.0.0.1 - - [13/Dec/2019 00:52:27] "GET /submit?url=https://sun9-69.userapi.com/c824201/v824201969/17341f/IfCwbiGRL7c.jpg%22%27 HTTP/1.1" 500 -
2019-12-13 00:54:49,440  * Running on http://127.0.0.1:5000/ (Press CTRL+C to quit)
2019-12-13 00:54:58,329 Exception on /submit [GET]
Traceback (most recent call last):
  File "/Library/Frameworks/Python.framework/Versions/3.7/lib/python3.7/site-packages/flask/app.py", line 2446, in wsgi_app
    response = self.full_dispatch_request()
  File "/Library/Frameworks/Python.framework/Versions/3.7/lib/python3.7/site-packages/flask/app.py", line 1951, in full_dispatch_request
    rv = self.handle_user_exception(e)
  File "/Library/Frameworks/Python.framework/Versions/3.7/lib/python3.7/site-packages/flask/app.py", line 1820, in handle_user_exception
    reraise(exc_type, exc_value, tb)
  File "/Library/Frameworks/Python.framework/Versions/3.7/lib/python3.7/site-packages/flask/_compat.py", line 39, in reraise
    raise value
  File "/Library/Frameworks/Python.framework/Versions/3.7/lib/python3.7/site-packages/flask/app.py", line 1949, in full_dispatch_request
    rv = self.dispatch_request()
  File "/Library/Frameworks/Python.framework/Versions/3.7/lib/python3.7/site-packages/flask/app.py", line 1935, in dispatch_request
    return self.view_functions[rule.endpoint](**req.view_args)
  File "/Users/sergeykostitsin/MD5_service/server/flaskserv.py", line 44, in post
    task_id = create_task_with_id(url,email)
  File "/Users/sergeykostitsin/MD5_service/server/flaskserv.py", line 50, in create_task_with_id
    task = calc_hash_sum.delay(1)
  File "/Library/Frameworks/Python.framework/Versions/3.7/lib/python3.7/site-packages/celery/app/task.py", line 427, in delay
    return self.apply_async(args, kwargs)
  File "/Library/Frameworks/Python.framework/Versions/3.7/lib/python3.7/site-packages/celery/app/task.py", line 532, in apply_async
    check_arguments(*(args or ()), **(kwargs or {}))
TypeError: calc_hash_sum() missing 1 required positional argument: 'url'
2019-12-13 00:54:58,334 127.0.0.1 - - [13/Dec/2019 00:54:58] "GET /submit?url=https://sun9-69.userapi.com/c824201/v824201969/17341f/IfCwbiGRL7c.jpg%22%27 HTTP/1.1" 500 -
2019-12-13 00:55:34,384  * Running on http://127.0.0.1:5000/ (Press CTRL+C to quit)
2019-12-13 00:55:38,047 Exception on /submit [GET]
Traceback (most recent call last):
  File "/Library/Frameworks/Python.framework/Versions/3.7/lib/python3.7/site-packages/flask/app.py", line 2446, in wsgi_app
    response = self.full_dispatch_request()
  File "/Library/Frameworks/Python.framework/Versions/3.7/lib/python3.7/site-packages/flask/app.py", line 1951, in full_dispatch_request
    rv = self.handle_user_exception(e)
  File "/Library/Frameworks/Python.framework/Versions/3.7/lib/python3.7/site-packages/flask/app.py", line 1820, in handle_user_exception
    reraise(exc_type, exc_value, tb)
  File "/Library/Frameworks/Python.framework/Versions/3.7/lib/python3.7/site-packages/flask/_compat.py", line 39, in reraise
    raise value
  File "/Library/Frameworks/Python.framework/Versions/3.7/lib/python3.7/site-packages/flask/app.py", line 1949, in full_dispatch_request
    rv = self.dispatch_request()
  File "/Library/Frameworks/Python.framework/Versions/3.7/lib/python3.7/site-packages/flask/app.py", line 1935, in dispatch_request
    return self.view_functions[rule.endpoint](**req.view_args)
  File "/Users/sergeykostitsin/MD5_service/server/flaskserv.py", line 44, in post
    task_id = create_task_with_id(url,email)
  File "/Users/sergeykostitsin/MD5_service/server/flaskserv.py", line 50, in create_task_with_id
    task = calc_hash_sum.delay('1')
  File "/Library/Frameworks/Python.framework/Versions/3.7/lib/python3.7/site-packages/celery/app/task.py", line 427, in delay
    return self.apply_async(args, kwargs)
  File "/Library/Frameworks/Python.framework/Versions/3.7/lib/python3.7/site-packages/celery/app/task.py", line 532, in apply_async
    check_arguments(*(args or ()), **(kwargs or {}))
TypeError: calc_hash_sum() missing 1 required positional argument: 'url'
2019-12-13 00:55:38,050 127.0.0.1 - - [13/Dec/2019 00:55:38] "GET /submit?url=https://sun9-69.userapi.com/c824201/v824201969/17341f/IfCwbiGRL7c.jpg%22%27 HTTP/1.1" 500 -
2019-12-13 00:56:05,729  * Running on http://127.0.0.1:5000/ (Press CTRL+C to quit)
2019-12-13 00:56:08,266 127.0.0.1 - - [13/Dec/2019 00:56:08] "GET /submit?url=https://sun9-69.userapi.com/c824201/v824201969/17341f/IfCwbiGRL7c.jpg%22%27 HTTP/1.1" 200 -
2019-12-13 00:57:10,974  * Running on http://127.0.0.1:5000/ (Press CTRL+C to quit)
2019-12-13 00:57:13,849 Exception on /submit [GET]
Traceback (most recent call last):
  File "/Library/Frameworks/Python.framework/Versions/3.7/lib/python3.7/site-packages/flask/app.py", line 2446, in wsgi_app
    response = self.full_dispatch_request()
  File "/Library/Frameworks/Python.framework/Versions/3.7/lib/python3.7/site-packages/flask/app.py", line 1951, in full_dispatch_request
    rv = self.handle_user_exception(e)
  File "/Library/Frameworks/Python.framework/Versions/3.7/lib/python3.7/site-packages/flask/app.py", line 1820, in handle_user_exception
    reraise(exc_type, exc_value, tb)
  File "/Library/Frameworks/Python.framework/Versions/3.7/lib/python3.7/site-packages/flask/_compat.py", line 39, in reraise
    raise value
  File "/Library/Frameworks/Python.framework/Versions/3.7/lib/python3.7/site-packages/flask/app.py", line 1949, in full_dispatch_request
    rv = self.dispatch_request()
  File "/Library/Frameworks/Python.framework/Versions/3.7/lib/python3.7/site-packages/flask/app.py", line 1935, in dispatch_request
    return self.view_functions[rule.endpoint](**req.view_args)
  File "/Users/sergeykostitsin/MD5_service/server/flaskserv.py", line 44, in post
    task_id = create_task_with_id(url,email)
  File "/Users/sergeykostitsin/MD5_service/server/flaskserv.py", line 50, in create_task_with_id
    task = calc_hash_sum.delay()
  File "/Library/Frameworks/Python.framework/Versions/3.7/lib/python3.7/site-packages/celery/app/task.py", line 427, in delay
    return self.apply_async(args, kwargs)
  File "/Library/Frameworks/Python.framework/Versions/3.7/lib/python3.7/site-packages/celery/app/task.py", line 532, in apply_async
    check_arguments(*(args or ()), **(kwargs or {}))
TypeError: calc_hash_sum() missing 1 required positional argument: 'self'
2019-12-13 00:57:13,852 127.0.0.1 - - [13/Dec/2019 00:57:13] "GET /submit?url=https://sun9-69.userapi.com/c824201/v824201969/17341f/IfCwbiGRL7c.jpg%22%27 HTTP/1.1" 500 -
2019-12-13 00:57:36,706  * Running on http://127.0.0.1:5000/ (Press CTRL+C to quit)
2019-12-13 00:57:42,296 127.0.0.1 - - [13/Dec/2019 00:57:42] "GET /submit?url=https://sun9-69.userapi.com/c824201/v824201969/17341f/IfCwbiGRL7c.jpg%22%27 HTTP/1.1" 200 -
2019-12-13 00:58:03,836  * Running on http://127.0.0.1:5000/ (Press CTRL+C to quit)
2019-12-13 00:58:06,439 127.0.0.1 - - [13/Dec/2019 00:58:06] "GET /submit?url=https://sun9-69.userapi.com/c824201/v824201969/17341f/IfCwbiGRL7c.jpg%22%27 HTTP/1.1" 200 -
2019-12-13 00:58:49,124  * Running on http://127.0.0.1:5000/ (Press CTRL+C to quit)
2019-12-13 00:58:55,110 127.0.0.1 - - [13/Dec/2019 00:58:55] "GET /submit?url=https://sun9-69.userapi.com/c824201/v824201969/17341f/IfCwbiGRL7c.jpg%22%27 HTTP/1.1" 200 -
2019-12-13 01:10:01,246  * Running on http://127.0.0.1:5000/ (Press CTRL+C to quit)
2019-12-13 01:10:15,598 127.0.0.1 - - [13/Dec/2019 01:10:15] "GET /submit?url=https://sun9-69.userapi.com/c824201/v824201969/17341f/IfCwbiGRL7c.jpg%22%27 HTTP/1.1" 200 -
2019-12-13 01:11:52,083  * Running on http://127.0.0.1:5000/ (Press CTRL+C to quit)
2019-12-13 01:11:57,303 127.0.0.1 - - [13/Dec/2019 01:11:57] "GET /submit?url=https://sun9-69.userapi.com/c824201/v824201969/17341f/IfCwbiGRL7c.jpg%22%27 HTTP/1.1" 200 -
2019-12-13 01:12:55,802  * Running on http://127.0.0.1:5000/ (Press CTRL+C to quit)
2019-12-13 01:13:01,994 Exception on /submit [GET]
Traceback (most recent call last):
  File "/Library/Frameworks/Python.framework/Versions/3.7/lib/python3.7/site-packages/flask/app.py", line 2446, in wsgi_app
    response = self.full_dispatch_request()
  File "/Library/Frameworks/Python.framework/Versions/3.7/lib/python3.7/site-packages/flask/app.py", line 1951, in full_dispatch_request
    rv = self.handle_user_exception(e)
  File "/Library/Frameworks/Python.framework/Versions/3.7/lib/python3.7/site-packages/flask/app.py", line 1820, in handle_user_exception
    reraise(exc_type, exc_value, tb)
  File "/Library/Frameworks/Python.framework/Versions/3.7/lib/python3.7/site-packages/flask/_compat.py", line 39, in reraise
    raise value
  File "/Library/Frameworks/Python.framework/Versions/3.7/lib/python3.7/site-packages/flask/app.py", line 1949, in full_dispatch_request
    rv = self.dispatch_request()
  File "/Library/Frameworks/Python.framework/Versions/3.7/lib/python3.7/site-packages/flask/app.py", line 1935, in dispatch_request
    return self.view_functions[rule.endpoint](**req.view_args)
  File "/Users/sergeykostitsin/MD5_service/server/flaskserv.py", line 44, in post
    task_id = create_task_with_id(url,email)
  File "/Users/sergeykostitsin/MD5_service/server/flaskserv.py", line 50, in create_task_with_id
    task = calc_hash_sum.delay(url,mail)
  File "/Library/Frameworks/Python.framework/Versions/3.7/lib/python3.7/site-packages/celery/app/task.py", line 427, in delay
    return self.apply_async(args, kwargs)
  File "/Library/Frameworks/Python.framework/Versions/3.7/lib/python3.7/site-packages/celery/app/task.py", line 532, in apply_async
    check_arguments(*(args or ()), **(kwargs or {}))
TypeError: calc_hash_sum() takes from 1 to 2 positional arguments but 3 were given
2019-12-13 01:13:01,998 127.0.0.1 - - [13/Dec/2019 01:13:01] "GET /submit?url=https://sun9-69.userapi.com/c824201/v824201969/17341f/IfCwbiGRL7c.jpg%22%27 HTTP/1.1" 500 -
2019-12-13 01:13:30,059  * Running on http://127.0.0.1:5000/ (Press CTRL+C to quit)
2019-12-13 01:13:33,780 127.0.0.1 - - [13/Dec/2019 01:13:33] "GET /submit?url=https://sun9-69.userapi.com/c824201/v824201969/17341f/IfCwbiGRL7c.jpg%22%27 HTTP/1.1" 200 -
2019-12-13 01:15:11,669  * Running on http://127.0.0.1:5000/ (Press CTRL+C to quit)
2019-12-13 01:15:14,532 127.0.0.1 - - [13/Dec/2019 01:15:14] "GET /submit?url=https://sun9-69.userapi.com/c824201/v824201969/17341f/IfCwbiGRL7c.jpg%22%27 HTTP/1.1" 200 -
2019-12-13 01:20:34,425  * Running on http://127.0.0.1:5000/ (Press CTRL+C to quit)
2019-12-13 01:20:39,306 127.0.0.1 - - [13/Dec/2019 01:20:39] "GET /submit?url=https://sun9-69.userapi.com/c824201/v824201969/17341f/IfCwbiGRL7c.jpg%22%27 HTTP/1.1" 200 -
2019-12-13 01:21:49,059  * Running on http://127.0.0.1:5000/ (Press CTRL+C to quit)
2019-12-13 01:21:51,520 127.0.0.1 - - [13/Dec/2019 01:21:51] "GET /submit?url=https://sun9-69.userapi.com/c824201/v824201969/17341f/IfCwbiGRL7c.jpg%22%27 HTTP/1.1" 200 -
2019-12-13 01:23:42,703  * Running on http://127.0.0.1:5000/ (Press CTRL+C to quit)
2019-12-13 01:23:52,857 127.0.0.1 - - [13/Dec/2019 01:23:52] "GET /submit?url=https://sun9-69.userapi.com/c824201/v824201969/17341f/IfCwbiGRL7c.jpg%22%27 HTTP/1.1" 200 -
2019-12-13 01:32:39,182  * Running on http://127.0.0.1:5000/ (Press CTRL+C to quit)
2019-12-13 01:33:46,421  * Running on http://127.0.0.1:5000/ (Press CTRL+C to quit)
2019-12-13 01:34:47,565  * Running on http://127.0.0.1:5000/ (Press CTRL+C to quit)
2019-12-13 01:34:50,071 127.0.0.1 - - [13/Dec/2019 01:34:50] "GET /submit?url=https://sun9-69.userapi.com/c824201/v824201969/17341f/IfCwbiGRL7c.jpg%22%27 HTTP/1.1" 200 -
2019-12-13 01:35:46,506  * Running on http://127.0.0.1:5000/ (Press CTRL+C to quit)
2019-12-13 01:35:48,983 127.0.0.1 - - [13/Dec/2019 01:35:48] "GET /submit?url=https://sun9-69.userapi.com/c824201/v824201969/17341f/IfCwbiGRL7c.jpg%22%27 HTTP/1.1" 200 -
2019-12-13 01:36:09,874  * Running on http://127.0.0.1:5000/ (Press CTRL+C to quit)
2019-12-13 01:36:35,676  * Running on http://127.0.0.1:5000/ (Press CTRL+C to quit)
2019-12-13 01:36:44,341 Exception on /submit [GET]
Traceback (most recent call last):
  File "/Library/Frameworks/Python.framework/Versions/3.7/lib/python3.7/site-packages/celery/backends/asynchronous.py", line 255, in _wait_for_pending
    on_interval=on_interval):
  File "/Library/Frameworks/Python.framework/Versions/3.7/lib/python3.7/site-packages/celery/backends/asynchronous.py", line 54, in drain_events_until
    raise socket.timeout()
socket.timeout

During handling of the above exception, another exception occurred:

Traceback (most recent call last):
  File "/Library/Frameworks/Python.framework/Versions/3.7/lib/python3.7/site-packages/flask/app.py", line 2446, in wsgi_app
    response = self.full_dispatch_request()
  File "/Library/Frameworks/Python.framework/Versions/3.7/lib/python3.7/site-packages/flask/app.py", line 1951, in full_dispatch_request
    rv = self.handle_user_exception(e)
  File "/Library/Frameworks/Python.framework/Versions/3.7/lib/python3.7/site-packages/flask/app.py", line 1820, in handle_user_exception
    reraise(exc_type, exc_value, tb)
  File "/Library/Frameworks/Python.framework/Versions/3.7/lib/python3.7/site-packages/flask/_compat.py", line 39, in reraise
    raise value
  File "/Library/Frameworks/Python.framework/Versions/3.7/lib/python3.7/site-packages/flask/app.py", line 1949, in full_dispatch_request
    rv = self.dispatch_request()
  File "/Library/Frameworks/Python.framework/Versions/3.7/lib/python3.7/site-packages/flask/app.py", line 1935, in dispatch_request
    return self.view_functions[rule.endpoint](**req.view_args)
  File "/Users/sergeykostitsin/MD5_service/server/flaskserv.py", line 40, in post
    task_id = create_task_with_id(url,email)
  File "/Users/sergeykostitsin/MD5_service/server/flaskserv.py", line 47, in create_task_with_id
    a = task.wait(5)
  File "/Library/Frameworks/Python.framework/Versions/3.7/lib/python3.7/site-packages/celery/result.py", line 226, in get
    on_message=on_message,
  File "/Library/Frameworks/Python.framework/Versions/3.7/lib/python3.7/site-packages/celery/backends/asynchronous.py", line 188, in wait_for_pending
    for _ in self._wait_for_pending(result, **kwargs):
  File "/Library/Frameworks/Python.framework/Versions/3.7/lib/python3.7/site-packages/celery/backends/asynchronous.py", line 259, in _wait_for_pending
    raise TimeoutError('The operation timed out.')
celery.exceptions.TimeoutError: The operation timed out.
2019-12-13 01:36:44,348 127.0.0.1 - - [13/Dec/2019 01:36:44] "GET /submit?url=https://sun9-69.userapi.com/c824201/v824201969/17341f/IfCwbiGRL7c.jpg%22%27 HTTP/1.1" 500 -
2019-12-13 01:37:30,220 Exception on /submit [GET]
Traceback (most recent call last):
  File "/Library/Frameworks/Python.framework/Versions/3.7/lib/python3.7/site-packages/celery/backends/asynchronous.py", line 255, in _wait_for_pending
    on_interval=on_interval):
  File "/Library/Frameworks/Python.framework/Versions/3.7/lib/python3.7/site-packages/celery/backends/asynchronous.py", line 54, in drain_events_until
    raise socket.timeout()
socket.timeout

During handling of the above exception, another exception occurred:

Traceback (most recent call last):
  File "/Library/Frameworks/Python.framework/Versions/3.7/lib/python3.7/site-packages/flask/app.py", line 2446, in wsgi_app
    response = self.full_dispatch_request()
  File "/Library/Frameworks/Python.framework/Versions/3.7/lib/python3.7/site-packages/flask/app.py", line 1951, in full_dispatch_request
    rv = self.handle_user_exception(e)
  File "/Library/Frameworks/Python.framework/Versions/3.7/lib/python3.7/site-packages/flask/app.py", line 1820, in handle_user_exception
    reraise(exc_type, exc_value, tb)
  File "/Library/Frameworks/Python.framework/Versions/3.7/lib/python3.7/site-packages/flask/_compat.py", line 39, in reraise
    raise value
  File "/Library/Frameworks/Python.framework/Versions/3.7/lib/python3.7/site-packages/flask/app.py", line 1949, in full_dispatch_request
    rv = self.dispatch_request()
  File "/Library/Frameworks/Python.framework/Versions/3.7/lib/python3.7/site-packages/flask/app.py", line 1935, in dispatch_request
    return self.view_functions[rule.endpoint](**req.view_args)
  File "/Users/sergeykostitsin/MD5_service/server/flaskserv.py", line 40, in post
    task_id = create_task_with_id(url,email)
  File "/Users/sergeykostitsin/MD5_service/server/flaskserv.py", line 47, in create_task_with_id
    a = task.wait(5)
  File "/Library/Frameworks/Python.framework/Versions/3.7/lib/python3.7/site-packages/celery/result.py", line 226, in get
    on_message=on_message,
  File "/Library/Frameworks/Python.framework/Versions/3.7/lib/python3.7/site-packages/celery/backends/asynchronous.py", line 188, in wait_for_pending
    for _ in self._wait_for_pending(result, **kwargs):
  File "/Library/Frameworks/Python.framework/Versions/3.7/lib/python3.7/site-packages/celery/backends/asynchronous.py", line 259, in _wait_for_pending
    raise TimeoutError('The operation timed out.')
celery.exceptions.TimeoutError: The operation timed out.
2019-12-13 01:37:30,222 127.0.0.1 - - [13/Dec/2019 01:37:30] "GET /submit?url=https://sun9-69.userapi.com/c824201/v824201969/17341f/IfCwbiGRL7c.jpg%22%27 HTTP/1.1" 500 -
2019-12-13 01:39:17,550 Exception on /submit [GET]
Traceback (most recent call last):
  File "/Library/Frameworks/Python.framework/Versions/3.7/lib/python3.7/site-packages/celery/backends/asynchronous.py", line 255, in _wait_for_pending
    on_interval=on_interval):
  File "/Library/Frameworks/Python.framework/Versions/3.7/lib/python3.7/site-packages/celery/backends/asynchronous.py", line 54, in drain_events_until
    raise socket.timeout()
socket.timeout

During handling of the above exception, another exception occurred:

Traceback (most recent call last):
  File "/Library/Frameworks/Python.framework/Versions/3.7/lib/python3.7/site-packages/flask/app.py", line 2446, in wsgi_app
    response = self.full_dispatch_request()
  File "/Library/Frameworks/Python.framework/Versions/3.7/lib/python3.7/site-packages/flask/app.py", line 1951, in full_dispatch_request
    rv = self.handle_user_exception(e)
  File "/Library/Frameworks/Python.framework/Versions/3.7/lib/python3.7/site-packages/flask/app.py", line 1820, in handle_user_exception
    reraise(exc_type, exc_value, tb)
  File "/Library/Frameworks/Python.framework/Versions/3.7/lib/python3.7/site-packages/flask/_compat.py", line 39, in reraise
    raise value
  File "/Library/Frameworks/Python.framework/Versions/3.7/lib/python3.7/site-packages/flask/app.py", line 1949, in full_dispatch_request
    rv = self.dispatch_request()
  File "/Library/Frameworks/Python.framework/Versions/3.7/lib/python3.7/site-packages/flask/app.py", line 1935, in dispatch_request
    return self.view_functions[rule.endpoint](**req.view_args)
  File "/Users/sergeykostitsin/MD5_service/server/flaskserv.py", line 40, in post
    task_id = create_task_with_id(url,email)
  File "/Users/sergeykostitsin/MD5_service/server/flaskserv.py", line 47, in create_task_with_id
    #logging.info(f'{a}')
  File "/Library/Frameworks/Python.framework/Versions/3.7/lib/python3.7/site-packages/celery/result.py", line 226, in get
    on_message=on_message,
  File "/Library/Frameworks/Python.framework/Versions/3.7/lib/python3.7/site-packages/celery/backends/asynchronous.py", line 188, in wait_for_pending
    for _ in self._wait_for_pending(result, **kwargs):
  File "/Library/Frameworks/Python.framework/Versions/3.7/lib/python3.7/site-packages/celery/backends/asynchronous.py", line 259, in _wait_for_pending
    raise TimeoutError('The operation timed out.')
celery.exceptions.TimeoutError: The operation timed out.
2019-12-13 01:39:17,556 127.0.0.1 - - [13/Dec/2019 01:39:17] "GET /submit?url=https://sun9-69.userapi.com/c824201/v824201969/17341f/IfCwbiGRL7c.jpg%22%27 HTTP/1.1" 500 -
2019-12-13 01:42:23,624  * Running on http://127.0.0.1:5000/ (Press CTRL+C to quit)
2019-12-13 01:42:29,467 127.0.0.1 - - [13/Dec/2019 01:42:29] "GET /submit?url=https://sun9-69.userapi.com/c824201/v824201969/17341f/IfCwbiGRL7c.jpg%22%27 HTTP/1.1" 200 -
2019-12-13 01:51:55,582  * Running on http://127.0.0.1:5000/ (Press CTRL+C to quit)
2019-12-13 01:52:01,228 127.0.0.1 - - [13/Dec/2019 01:52:01] "GET /submit?url=https://sun9-69.userapi.com/c824201/v824201969/17341f/IfCwbiGRL7c.jpg%22%27 HTTP/1.1" 200 -
2019-12-13 01:53:14,769 127.0.0.1 - - [13/Dec/2019 01:53:14] "GET /submit?url=https://sun9-69.userapi.com/c824201/v824201969/17341f/IfCwbiGRL7c.jpg%22%27 HTTP/1.1" 200 -
2019-12-13 01:53:22,314 127.0.0.1 - - [13/Dec/2019 01:53:22] "GET / HTTP/1.1" 404 -
2019-12-13 01:53:29,334 127.0.0.1 - - [13/Dec/2019 01:53:29] "GET /check?id=2 HTTP/1.1" 200 -
2019-12-13 01:53:33,045 127.0.0.1 - - [13/Dec/2019 01:53:33] "GET /check?id=2 HTTP/1.1" 200 -
2019-12-13 01:53:34,587 127.0.0.1 - - [13/Dec/2019 01:53:34] "GET / HTTP/1.1" 404 -
2019-12-13 01:53:35,200 127.0.0.1 - - [13/Dec/2019 01:53:35] "GET /submit?url=https://sun9-69.userapi.com/c824201/v824201969/17341f/IfCwbiGRL7c.jpg HTTP/1.1" 200 -
2019-12-13 01:53:54,839 127.0.0.1 - - [13/Dec/2019 01:53:54] "GET /submit?url=https://sun9-24.userapi.com/c840132/v840132969/40916/Tr3HbZNuvbY.jpg HTTP/1.1" 200 -
2019-12-13 01:53:54,953 127.0.0.1 - - [13/Dec/2019 01:53:54] "GET /favicon.ico HTTP/1.1" 404 -
2019-12-13 15:10:41,231  * Running on http://127.0.0.1:5000/ (Press CTRL+C to quit)
2019-12-13 15:10:48,174 127.0.0.1 - - [13/Dec/2019 15:10:48] "GET /submit?url=https://sun9-24.userapi.com/c840132/v840132969/40916/Tr3HbZNuvbY.jpg HTTP/1.1" 200 -
2019-12-13 15:31:10,886  * Running on http://127.0.0.1:5000/ (Press CTRL+C to quit)
2019-12-13 15:31:16,843 Exception on /submit [GET]
Traceback (most recent call last):
  File "/Library/Frameworks/Python.framework/Versions/3.7/lib/python3.7/site-packages/flask/app.py", line 2446, in wsgi_app
    response = self.full_dispatch_request()
  File "/Library/Frameworks/Python.framework/Versions/3.7/lib/python3.7/site-packages/flask/app.py", line 1951, in full_dispatch_request
    rv = self.handle_user_exception(e)
  File "/Library/Frameworks/Python.framework/Versions/3.7/lib/python3.7/site-packages/flask/app.py", line 1820, in handle_user_exception
    reraise(exc_type, exc_value, tb)
  File "/Library/Frameworks/Python.framework/Versions/3.7/lib/python3.7/site-packages/flask/_compat.py", line 39, in reraise
    raise value
  File "/Library/Frameworks/Python.framework/Versions/3.7/lib/python3.7/site-packages/flask/app.py", line 1949, in full_dispatch_request
    rv = self.dispatch_request()
  File "/Library/Frameworks/Python.framework/Versions/3.7/lib/python3.7/site-packages/flask/app.py", line 1935, in dispatch_request
    return self.view_functions[rule.endpoint](**req.view_args)
  File "/Users/sergeykostitsin/MD5_service/server/flaskserv.py", line 40, in post
    task_id = create_task_with_id(url,email)
  File "/Users/sergeykostitsin/MD5_service/server/flaskserv.py", line 46, in create_task_with_id
    task = calc_hash_sum.apply_async(url,mail)
  File "/Library/Frameworks/Python.framework/Versions/3.7/lib/python3.7/site-packages/celery/app/task.py", line 532, in apply_async
    check_arguments(*(args or ()), **(kwargs or {}))
TypeError: calc_hash_sum() argument after ** must be a mapping, not str
2019-12-13 15:31:16,847 127.0.0.1 - - [13/Dec/2019 15:31:16] "GET /submit?url=https://sun9-24.userapi.com/c840132/v840132969/40916/Tr3HbZNuvbY.jpg HTTP/1.1" 500 -
2019-12-13 15:31:49,664  * Running on http://127.0.0.1:5000/ (Press CTRL+C to quit)
2019-12-13 15:31:52,632 127.0.0.1 - - [13/Dec/2019 15:31:52] "GET /submit?url=https://sun9-24.userapi.com/c840132/v840132969/40916/Tr3HbZNuvbY.jpg HTTP/1.1" 200 -
2019-12-13 15:33:23,836  * Running on http://127.0.0.1:5000/ (Press CTRL+C to quit)
2019-12-13 15:33:29,027 127.0.0.1 - - [13/Dec/2019 15:33:29] "GET /submit?url=https://sun9-24.userapi.com/c840132/v840132969/40916/Tr3HbZNuvbY.jpg HTTP/1.1" 200 -
2019-12-14 13:17:35,026  * Running on http://127.0.0.1:5000/ (Press CTRL+C to quit)
2019-12-14 13:17:40,284 127.0.0.1 - - [14/Dec/2019 13:17:40] "GET /submit?url=https://sun9-24.userapi.com/c840132/v840132969/40916/Tr3HbZNuvbY.jpg HTTP/1.1" 200 -
2019-12-14 13:18:40,658  * Running on http://127.0.0.1:5000/ (Press CTRL+C to quit)
2019-12-14 13:18:43,585 after
2019-12-14 13:18:43,591 127.0.0.1 - - [14/Dec/2019 13:18:43] "GET /submit?url=https://sun9-24.userapi.com/c840132/v840132969/40916/Tr3HbZNuvbY.jpg HTTP/1.1" 200 -
2019-12-14 13:21:11,518  * Running on http://127.0.0.1:5000/ (Press CTRL+C to quit)
2019-12-14 13:21:27,432 after
2019-12-14 13:21:27,440 127.0.0.1 - - [14/Dec/2019 13:21:27] "GET /submit?url=https://sun9-24.userapi.com/c840132/v840132969/40916/Tr3HbZNuvbY.jpg HTTP/1.1" 200 -
2019-12-14 13:24:50,101 after
2019-12-14 13:24:50,106 127.0.0.1 - - [14/Dec/2019 13:24:50] "GET /submit?url=https://sun9-24.userapi.com/c840132/v840132969/40916/Tr3HbZNuvbY.jpg HTTP/1.1" 200 -
2019-12-14 13:24:51,437 after
2019-12-14 13:24:51,441 127.0.0.1 - - [14/Dec/2019 13:24:51] "GET /submit?url=https://sun9-24.userapi.com/c840132/v840132969/40916/Tr3HbZNuvbY.jpg HTTP/1.1" 200 -
2019-12-14 13:24:52,938 after
2019-12-14 13:24:52,940 127.0.0.1 - - [14/Dec/2019 13:24:52] "GET /submit?url=https://sun9-24.userapi.com/c840132/v840132969/40916/Tr3HbZNuvbY.jpg HTTP/1.1" 200 -
2019-12-14 13:24:59,010 after
2019-12-14 13:24:59,020 127.0.0.1 - - [14/Dec/2019 13:24:59] "GET /submit?url=https://sun9-24.userapi.com/c840132/v840132969/40916/Tr3HbZNuvbY.jpg HTTP/1.1" 200 -
2019-12-14 13:25:00,353 after
2019-12-14 13:25:00,355 127.0.0.1 - - [14/Dec/2019 13:25:00] "GET /submit?url=https://sun9-24.userapi.com/c840132/v840132969/40916/Tr3HbZNuvbY.jpg HTTP/1.1" 200 -
2019-12-14 13:25:01,220 after
2019-12-14 13:25:01,221 127.0.0.1 - - [14/Dec/2019 13:25:01] "GET /submit?url=https://sun9-24.userapi.com/c840132/v840132969/40916/Tr3HbZNuvbY.jpg HTTP/1.1" 200 -
2019-12-14 13:25:30,123  * Running on http://127.0.0.1:5000/ (Press CTRL+C to quit)
2019-12-14 13:25:33,950 Exception on /submit [GET]
Traceback (most recent call last):
  File "/Library/Frameworks/Python.framework/Versions/3.7/lib/python3.7/site-packages/flask/app.py", line 2446, in wsgi_app
    response = self.full_dispatch_request()
  File "/Library/Frameworks/Python.framework/Versions/3.7/lib/python3.7/site-packages/flask/app.py", line 1951, in full_dispatch_request
    rv = self.handle_user_exception(e)
  File "/Library/Frameworks/Python.framework/Versions/3.7/lib/python3.7/site-packages/flask/app.py", line 1820, in handle_user_exception
    reraise(exc_type, exc_value, tb)
  File "/Library/Frameworks/Python.framework/Versions/3.7/lib/python3.7/site-packages/flask/_compat.py", line 39, in reraise
    raise value
  File "/Library/Frameworks/Python.framework/Versions/3.7/lib/python3.7/site-packages/flask/app.py", line 1949, in full_dispatch_request
    rv = self.dispatch_request()
  File "/Library/Frameworks/Python.framework/Versions/3.7/lib/python3.7/site-packages/flask/app.py", line 1935, in dispatch_request
    return self.view_functions[rule.endpoint](**req.view_args)
  File "/Users/sergeykostitsin/MD5_service/server/flaskserv.py", line 40, in post
    task_id = create_task_with_id(url,email)
  File "/Users/sergeykostitsin/MD5_service/server/flaskserv.py", line 46, in create_task_with_id
    task = calc_hash_sum.apply_async(url,mail)
  File "/Library/Frameworks/Python.framework/Versions/3.7/lib/python3.7/site-packages/celery/app/task.py", line 532, in apply_async
    check_arguments(*(args or ()), **(kwargs or {}))
TypeError: calc_hash_sum() argument after ** must be a mapping, not str
2019-12-14 13:25:33,954 127.0.0.1 - - [14/Dec/2019 13:25:33] "GET /submit?url=https://sun9-24.userapi.com/c840132/v840132969/40916/Tr3HbZNuvbY.jpg HTTP/1.1" 500 -
2019-12-14 13:25:35,085 Exception on /submit [GET]
Traceback (most recent call last):
  File "/Library/Frameworks/Python.framework/Versions/3.7/lib/python3.7/site-packages/flask/app.py", line 2446, in wsgi_app
    response = self.full_dispatch_request()
  File "/Library/Frameworks/Python.framework/Versions/3.7/lib/python3.7/site-packages/flask/app.py", line 1951, in full_dispatch_request
    rv = self.handle_user_exception(e)
  File "/Library/Frameworks/Python.framework/Versions/3.7/lib/python3.7/site-packages/flask/app.py", line 1820, in handle_user_exception
    reraise(exc_type, exc_value, tb)
  File "/Library/Frameworks/Python.framework/Versions/3.7/lib/python3.7/site-packages/flask/_compat.py", line 39, in reraise
    raise value
  File "/Library/Frameworks/Python.framework/Versions/3.7/lib/python3.7/site-packages/flask/app.py", line 1949, in full_dispatch_request
    rv = self.dispatch_request()
  File "/Library/Frameworks/Python.framework/Versions/3.7/lib/python3.7/site-packages/flask/app.py", line 1935, in dispatch_request
    return self.view_functions[rule.endpoint](**req.view_args)
  File "/Users/sergeykostitsin/MD5_service/server/flaskserv.py", line 40, in post
    task_id = create_task_with_id(url,email)
  File "/Users/sergeykostitsin/MD5_service/server/flaskserv.py", line 46, in create_task_with_id
    task = calc_hash_sum.apply_async(url,mail)
  File "/Library/Frameworks/Python.framework/Versions/3.7/lib/python3.7/site-packages/celery/app/task.py", line 532, in apply_async
    check_arguments(*(args or ()), **(kwargs or {}))
TypeError: calc_hash_sum() argument after ** must be a mapping, not str
2019-12-14 13:25:35,086 127.0.0.1 - - [14/Dec/2019 13:25:35] "GET /submit?url=https://sun9-24.userapi.com/c840132/v840132969/40916/Tr3HbZNuvbY.jpg HTTP/1.1" 500 -
2019-12-14 13:25:35,893 Exception on /submit [GET]
Traceback (most recent call last):
  File "/Library/Frameworks/Python.framework/Versions/3.7/lib/python3.7/site-packages/flask/app.py", line 2446, in wsgi_app
    response = self.full_dispatch_request()
  File "/Library/Frameworks/Python.framework/Versions/3.7/lib/python3.7/site-packages/flask/app.py", line 1951, in full_dispatch_request
    rv = self.handle_user_exception(e)
  File "/Library/Frameworks/Python.framework/Versions/3.7/lib/python3.7/site-packages/flask/app.py", line 1820, in handle_user_exception
    reraise(exc_type, exc_value, tb)
  File "/Library/Frameworks/Python.framework/Versions/3.7/lib/python3.7/site-packages/flask/_compat.py", line 39, in reraise
    raise value
  File "/Library/Frameworks/Python.framework/Versions/3.7/lib/python3.7/site-packages/flask/app.py", line 1949, in full_dispatch_request
    rv = self.dispatch_request()
  File "/Library/Frameworks/Python.framework/Versions/3.7/lib/python3.7/site-packages/flask/app.py", line 1935, in dispatch_request
    return self.view_functions[rule.endpoint](**req.view_args)
  File "/Users/sergeykostitsin/MD5_service/server/flaskserv.py", line 40, in post
    task_id = create_task_with_id(url,email)
  File "/Users/sergeykostitsin/MD5_service/server/flaskserv.py", line 46, in create_task_with_id
    task = calc_hash_sum.apply_async(url,mail)
  File "/Library/Frameworks/Python.framework/Versions/3.7/lib/python3.7/site-packages/celery/app/task.py", line 532, in apply_async
    check_arguments(*(args or ()), **(kwargs or {}))
TypeError: calc_hash_sum() argument after ** must be a mapping, not str
2019-12-14 13:25:35,894 127.0.0.1 - - [14/Dec/2019 13:25:35] "GET /submit?url=https://sun9-24.userapi.com/c840132/v840132969/40916/Tr3HbZNuvbY.jpg HTTP/1.1" 500 -
2019-12-14 13:25:36,677 Exception on /submit [GET]
Traceback (most recent call last):
  File "/Library/Frameworks/Python.framework/Versions/3.7/lib/python3.7/site-packages/flask/app.py", line 2446, in wsgi_app
    response = self.full_dispatch_request()
  File "/Library/Frameworks/Python.framework/Versions/3.7/lib/python3.7/site-packages/flask/app.py", line 1951, in full_dispatch_request
    rv = self.handle_user_exception(e)
  File "/Library/Frameworks/Python.framework/Versions/3.7/lib/python3.7/site-packages/flask/app.py", line 1820, in handle_user_exception
    reraise(exc_type, exc_value, tb)
  File "/Library/Frameworks/Python.framework/Versions/3.7/lib/python3.7/site-packages/flask/_compat.py", line 39, in reraise
    raise value
  File "/Library/Frameworks/Python.framework/Versions/3.7/lib/python3.7/site-packages/flask/app.py", line 1949, in full_dispatch_request
    rv = self.dispatch_request()
  File "/Library/Frameworks/Python.framework/Versions/3.7/lib/python3.7/site-packages/flask/app.py", line 1935, in dispatch_request
    return self.view_functions[rule.endpoint](**req.view_args)
  File "/Users/sergeykostitsin/MD5_service/server/flaskserv.py", line 40, in post
    task_id = create_task_with_id(url,email)
  File "/Users/sergeykostitsin/MD5_service/server/flaskserv.py", line 46, in create_task_with_id
    task = calc_hash_sum.apply_async(url,mail)
  File "/Library/Frameworks/Python.framework/Versions/3.7/lib/python3.7/site-packages/celery/app/task.py", line 532, in apply_async
    check_arguments(*(args or ()), **(kwargs or {}))
TypeError: calc_hash_sum() argument after ** must be a mapping, not str
2019-12-14 13:25:36,677 127.0.0.1 - - [14/Dec/2019 13:25:36] "GET /submit?url=https://sun9-24.userapi.com/c840132/v840132969/40916/Tr3HbZNuvbY.jpg HTTP/1.1" 500 -
2019-12-14 13:25:37,451 Exception on /submit [GET]
Traceback (most recent call last):
  File "/Library/Frameworks/Python.framework/Versions/3.7/lib/python3.7/site-packages/flask/app.py", line 2446, in wsgi_app
    response = self.full_dispatch_request()
  File "/Library/Frameworks/Python.framework/Versions/3.7/lib/python3.7/site-packages/flask/app.py", line 1951, in full_dispatch_request
    rv = self.handle_user_exception(e)
  File "/Library/Frameworks/Python.framework/Versions/3.7/lib/python3.7/site-packages/flask/app.py", line 1820, in handle_user_exception
    reraise(exc_type, exc_value, tb)
  File "/Library/Frameworks/Python.framework/Versions/3.7/lib/python3.7/site-packages/flask/_compat.py", line 39, in reraise
    raise value
  File "/Library/Frameworks/Python.framework/Versions/3.7/lib/python3.7/site-packages/flask/app.py", line 1949, in full_dispatch_request
    rv = self.dispatch_request()
  File "/Library/Frameworks/Python.framework/Versions/3.7/lib/python3.7/site-packages/flask/app.py", line 1935, in dispatch_request
    return self.view_functions[rule.endpoint](**req.view_args)
  File "/Users/sergeykostitsin/MD5_service/server/flaskserv.py", line 40, in post
    task_id = create_task_with_id(url,email)
  File "/Users/sergeykostitsin/MD5_service/server/flaskserv.py", line 46, in create_task_with_id
    task = calc_hash_sum.apply_async(url,mail)
  File "/Library/Frameworks/Python.framework/Versions/3.7/lib/python3.7/site-packages/celery/app/task.py", line 532, in apply_async
    check_arguments(*(args or ()), **(kwargs or {}))
TypeError: calc_hash_sum() argument after ** must be a mapping, not str
2019-12-14 13:25:37,452 127.0.0.1 - - [14/Dec/2019 13:25:37] "GET /submit?url=https://sun9-24.userapi.com/c840132/v840132969/40916/Tr3HbZNuvbY.jpg HTTP/1.1" 500 -
2019-12-14 13:27:51,662  * Running on http://127.0.0.1:5000/ (Press CTRL+C to quit)
2019-12-14 13:27:58,372 after
2019-12-14 13:27:58,407 127.0.0.1 - - [14/Dec/2019 13:27:58] "GET /submit?url=https://sun9-24.userapi.com/c840132/v840132969/40916/Tr3HbZNuvbY.jpg HTTP/1.1" 200 -
2019-12-14 13:27:59,160 after
2019-12-14 13:27:59,204 127.0.0.1 - - [14/Dec/2019 13:27:59] "GET /submit?url=https://sun9-24.userapi.com/c840132/v840132969/40916/Tr3HbZNuvbY.jpg HTTP/1.1" 200 -
2019-12-14 13:27:59,835 after
2019-12-14 13:27:59,836 127.0.0.1 - - [14/Dec/2019 13:27:59] "GET /submit?url=https://sun9-24.userapi.com/c840132/v840132969/40916/Tr3HbZNuvbY.jpg HTTP/1.1" 200 -
2019-12-14 13:28:00,453 after
2019-12-14 13:28:00,454 127.0.0.1 - - [14/Dec/2019 13:28:00] "GET /submit?url=https://sun9-24.userapi.com/c840132/v840132969/40916/Tr3HbZNuvbY.jpg HTTP/1.1" 200 -
2019-12-14 13:30:04,850  * Running on http://127.0.0.1:5000/ (Press CTRL+C to quit)
2019-12-14 13:30:09,679 after
2019-12-14 13:30:09,691 127.0.0.1 - - [14/Dec/2019 13:30:09] "GET /submit?url=https://sun9-24.userapi.com/c840132/v840132969/40916/Tr3HbZNuvbY.jpg HTTP/1.1" 200 -
2019-12-14 13:30:59,897  * Running on http://127.0.0.1:5000/ (Press CTRL+C to quit)
2019-12-14 13:31:05,433 after
2019-12-14 13:31:05,439 127.0.0.1 - - [14/Dec/2019 13:31:05] "GET /submit?url=https://sun9-24.userapi.com/c840132/v840132969/40916/Tr3HbZNuvbY.jpg HTTP/1.1" 200 -
2019-12-14 13:31:06,252 after
2019-12-14 13:31:06,254 127.0.0.1 - - [14/Dec/2019 13:31:06] "GET /submit?url=https://sun9-24.userapi.com/c840132/v840132969/40916/Tr3HbZNuvbY.jpg HTTP/1.1" 200 -
2019-12-14 13:33:21,415  * Running on http://127.0.0.1:5000/ (Press CTRL+C to quit)
2019-12-14 13:33:25,392 after
2019-12-14 13:33:25,402 127.0.0.1 - - [14/Dec/2019 13:33:25] "GET /submit?url=https://sun9-24.userapi.com/c840132/v840132969/40916/Tr3HbZNuvbY.jpg HTTP/1.1" 200 -
2019-12-14 13:37:45,062  * Running on http://127.0.0.1:5000/ (Press CTRL+C to quit)
2019-12-14 13:37:58,234 after
2019-12-14 13:37:58,291 127.0.0.1 - - [14/Dec/2019 13:37:58] "GET /submit?url=https://sun9-24.userapi.com/c840132/v840132969/40916/Tr3HbZNuvbY.jpg HTTP/1.1" 200 -
2019-12-14 13:39:15,071  * Running on http://127.0.0.1:5000/ (Press CTRL+C to quit)
2019-12-14 13:39:17,741 after
2019-12-14 13:39:17,749 127.0.0.1 - - [14/Dec/2019 13:39:17] "GET /submit?url=https://sun9-24.userapi.com/c840132/v840132969/40916/Tr3HbZNuvbY.jpg HTTP/1.1" 200 -
2019-12-14 13:39:19,902 after
2019-12-14 13:39:19,903 127.0.0.1 - - [14/Dec/2019 13:39:19] "GET /submit?url=https://sun9-24.userapi.com/c840132/v840132969/40916/Tr3HbZNuvbY.jpg HTTP/1.1" 200 -
2019-12-14 13:40:06,940  * Running on http://127.0.0.1:5000/ (Press CTRL+C to quit)
2019-12-14 13:40:09,374 127.0.0.1 - - [14/Dec/2019 13:40:09] "GET /submit?url=https://sun9-24.userapi.com/c840132/v840132969/40916/Tr3HbZNuvbY.jpg HTTP/1.1" 404 -
2019-12-14 13:40:42,856  * Running on http://127.0.0.1:5000/ (Press CTRL+C to quit)
2019-12-14 13:40:43,476 Exception on /submit [GET]
Traceback (most recent call last):
  File "/Library/Frameworks/Python.framework/Versions/3.7/lib/python3.7/site-packages/flask/app.py", line 2446, in wsgi_app
    response = self.full_dispatch_request()
  File "/Library/Frameworks/Python.framework/Versions/3.7/lib/python3.7/site-packages/flask/app.py", line 1951, in full_dispatch_request
    rv = self.handle_user_exception(e)
  File "/Library/Frameworks/Python.framework/Versions/3.7/lib/python3.7/site-packages/flask/app.py", line 1820, in handle_user_exception
    reraise(exc_type, exc_value, tb)
  File "/Library/Frameworks/Python.framework/Versions/3.7/lib/python3.7/site-packages/flask/_compat.py", line 39, in reraise
    raise value
  File "/Library/Frameworks/Python.framework/Versions/3.7/lib/python3.7/site-packages/flask/app.py", line 1949, in full_dispatch_request
    rv = self.dispatch_request()
  File "/Library/Frameworks/Python.framework/Versions/3.7/lib/python3.7/site-packages/flask/app.py", line 1935, in dispatch_request
    return self.view_functions[rule.endpoint](**req.view_args)
  File "/Users/sergeykostitsin/MD5_service/server/flaskserv.py", line 46, in post
    task_id = create_task_with_id(url,email)
NameError: name 'create_task_with_id' is not defined
2019-12-14 13:40:43,480 127.0.0.1 - - [14/Dec/2019 13:40:43] "GET /submit?url=https://sun9-24.userapi.com/c840132/v840132969/40916/Tr3HbZNuvbY.jpg HTTP/1.1" 500 -
2019-12-14 13:40:44,111 Exception on /submit [GET]
Traceback (most recent call last):
  File "/Library/Frameworks/Python.framework/Versions/3.7/lib/python3.7/site-packages/flask/app.py", line 2446, in wsgi_app
    response = self.full_dispatch_request()
  File "/Library/Frameworks/Python.framework/Versions/3.7/lib/python3.7/site-packages/flask/app.py", line 1951, in full_dispatch_request
    rv = self.handle_user_exception(e)
  File "/Library/Frameworks/Python.framework/Versions/3.7/lib/python3.7/site-packages/flask/app.py", line 1820, in handle_user_exception
    reraise(exc_type, exc_value, tb)
  File "/Library/Frameworks/Python.framework/Versions/3.7/lib/python3.7/site-packages/flask/_compat.py", line 39, in reraise
    raise value
  File "/Library/Frameworks/Python.framework/Versions/3.7/lib/python3.7/site-packages/flask/app.py", line 1949, in full_dispatch_request
    rv = self.dispatch_request()
  File "/Library/Frameworks/Python.framework/Versions/3.7/lib/python3.7/site-packages/flask/app.py", line 1935, in dispatch_request
    return self.view_functions[rule.endpoint](**req.view_args)
  File "/Users/sergeykostitsin/MD5_service/server/flaskserv.py", line 46, in post
    task_id = create_task_with_id(url,email)
NameError: name 'create_task_with_id' is not defined
2019-12-14 13:40:44,112 127.0.0.1 - - [14/Dec/2019 13:40:44] "GET /submit?url=https://sun9-24.userapi.com/c840132/v840132969/40916/Tr3HbZNuvbY.jpg HTTP/1.1" 500 -
2019-12-14 13:40:44,565 Exception on /submit [GET]
Traceback (most recent call last):
  File "/Library/Frameworks/Python.framework/Versions/3.7/lib/python3.7/site-packages/flask/app.py", line 2446, in wsgi_app
    response = self.full_dispatch_request()
  File "/Library/Frameworks/Python.framework/Versions/3.7/lib/python3.7/site-packages/flask/app.py", line 1951, in full_dispatch_request
    rv = self.handle_user_exception(e)
  File "/Library/Frameworks/Python.framework/Versions/3.7/lib/python3.7/site-packages/flask/app.py", line 1820, in handle_user_exception
    reraise(exc_type, exc_value, tb)
  File "/Library/Frameworks/Python.framework/Versions/3.7/lib/python3.7/site-packages/flask/_compat.py", line 39, in reraise
    raise value
  File "/Library/Frameworks/Python.framework/Versions/3.7/lib/python3.7/site-packages/flask/app.py", line 1949, in full_dispatch_request
    rv = self.dispatch_request()
  File "/Library/Frameworks/Python.framework/Versions/3.7/lib/python3.7/site-packages/flask/app.py", line 1935, in dispatch_request
    return self.view_functions[rule.endpoint](**req.view_args)
  File "/Users/sergeykostitsin/MD5_service/server/flaskserv.py", line 46, in post
    task_id = create_task_with_id(url,email)
NameError: name 'create_task_with_id' is not defined
2019-12-14 13:40:44,565 127.0.0.1 - - [14/Dec/2019 13:40:44] "GET /submit?url=https://sun9-24.userapi.com/c840132/v840132969/40916/Tr3HbZNuvbY.jpg HTTP/1.1" 500 -
2019-12-14 13:40:44,901 Exception on /submit [GET]
Traceback (most recent call last):
  File "/Library/Frameworks/Python.framework/Versions/3.7/lib/python3.7/site-packages/flask/app.py", line 2446, in wsgi_app
    response = self.full_dispatch_request()
  File "/Library/Frameworks/Python.framework/Versions/3.7/lib/python3.7/site-packages/flask/app.py", line 1951, in full_dispatch_request
    rv = self.handle_user_exception(e)
  File "/Library/Frameworks/Python.framework/Versions/3.7/lib/python3.7/site-packages/flask/app.py", line 1820, in handle_user_exception
    reraise(exc_type, exc_value, tb)
  File "/Library/Frameworks/Python.framework/Versions/3.7/lib/python3.7/site-packages/flask/_compat.py", line 39, in reraise
    raise value
  File "/Library/Frameworks/Python.framework/Versions/3.7/lib/python3.7/site-packages/flask/app.py", line 1949, in full_dispatch_request
    rv = self.dispatch_request()
  File "/Library/Frameworks/Python.framework/Versions/3.7/lib/python3.7/site-packages/flask/app.py", line 1935, in dispatch_request
    return self.view_functions[rule.endpoint](**req.view_args)
  File "/Users/sergeykostitsin/MD5_service/server/flaskserv.py", line 46, in post
    task_id = create_task_with_id(url,email)
NameError: name 'create_task_with_id' is not defined
2019-12-14 13:40:44,902 127.0.0.1 - - [14/Dec/2019 13:40:44] "GET /submit?url=https://sun9-24.userapi.com/c840132/v840132969/40916/Tr3HbZNuvbY.jpg HTTP/1.1" 500 -
2019-12-14 13:40:45,081 Exception on /submit [GET]
Traceback (most recent call last):
  File "/Library/Frameworks/Python.framework/Versions/3.7/lib/python3.7/site-packages/flask/app.py", line 2446, in wsgi_app
    response = self.full_dispatch_request()
  File "/Library/Frameworks/Python.framework/Versions/3.7/lib/python3.7/site-packages/flask/app.py", line 1951, in full_dispatch_request
    rv = self.handle_user_exception(e)
  File "/Library/Frameworks/Python.framework/Versions/3.7/lib/python3.7/site-packages/flask/app.py", line 1820, in handle_user_exception
    reraise(exc_type, exc_value, tb)
  File "/Library/Frameworks/Python.framework/Versions/3.7/lib/python3.7/site-packages/flask/_compat.py", line 39, in reraise
    raise value
  File "/Library/Frameworks/Python.framework/Versions/3.7/lib/python3.7/site-packages/flask/app.py", line 1949, in full_dispatch_request
    rv = self.dispatch_request()
  File "/Library/Frameworks/Python.framework/Versions/3.7/lib/python3.7/site-packages/flask/app.py", line 1935, in dispatch_request
    return self.view_functions[rule.endpoint](**req.view_args)
  File "/Users/sergeykostitsin/MD5_service/server/flaskserv.py", line 46, in post
    task_id = create_task_with_id(url,email)
NameError: name 'create_task_with_id' is not defined
2019-12-14 13:40:45,082 127.0.0.1 - - [14/Dec/2019 13:40:45] "GET /submit?url=https://sun9-24.userapi.com/c840132/v840132969/40916/Tr3HbZNuvbY.jpg HTTP/1.1" 500 -
2019-12-14 13:41:15,955  * Running on http://127.0.0.1:5000/ (Press CTRL+C to quit)
2019-12-14 13:41:17,066 Exception on /submit [GET]
Traceback (most recent call last):
  File "/Library/Frameworks/Python.framework/Versions/3.7/lib/python3.7/site-packages/flask/app.py", line 2446, in wsgi_app
    response = self.full_dispatch_request()
  File "/Library/Frameworks/Python.framework/Versions/3.7/lib/python3.7/site-packages/flask/app.py", line 1951, in full_dispatch_request
    rv = self.handle_user_exception(e)
  File "/Library/Frameworks/Python.framework/Versions/3.7/lib/python3.7/site-packages/flask/app.py", line 1820, in handle_user_exception
    reraise(exc_type, exc_value, tb)
  File "/Library/Frameworks/Python.framework/Versions/3.7/lib/python3.7/site-packages/flask/_compat.py", line 39, in reraise
    raise value
  File "/Library/Frameworks/Python.framework/Versions/3.7/lib/python3.7/site-packages/flask/app.py", line 1949, in full_dispatch_request
    rv = self.dispatch_request()
  File "/Library/Frameworks/Python.framework/Versions/3.7/lib/python3.7/site-packages/flask/app.py", line 1935, in dispatch_request
    return self.view_functions[rule.endpoint](**req.view_args)
  File "/Users/sergeykostitsin/MD5_service/server/flaskserv.py", line 48, in post
    return {'id': f'{task_id}'}
NameError: name 'task_id' is not defined
2019-12-14 13:41:17,068 127.0.0.1 - - [14/Dec/2019 13:41:17] "GET /submit?url=https://sun9-24.userapi.com/c840132/v840132969/40916/Tr3HbZNuvbY.jpg HTTP/1.1" 500 -
2019-12-14 13:41:18,668 Exception on /submit [GET]
Traceback (most recent call last):
  File "/Library/Frameworks/Python.framework/Versions/3.7/lib/python3.7/site-packages/flask/app.py", line 2446, in wsgi_app
    response = self.full_dispatch_request()
  File "/Library/Frameworks/Python.framework/Versions/3.7/lib/python3.7/site-packages/flask/app.py", line 1951, in full_dispatch_request
    rv = self.handle_user_exception(e)
  File "/Library/Frameworks/Python.framework/Versions/3.7/lib/python3.7/site-packages/flask/app.py", line 1820, in handle_user_exception
    reraise(exc_type, exc_value, tb)
  File "/Library/Frameworks/Python.framework/Versions/3.7/lib/python3.7/site-packages/flask/_compat.py", line 39, in reraise
    raise value
  File "/Library/Frameworks/Python.framework/Versions/3.7/lib/python3.7/site-packages/flask/app.py", line 1949, in full_dispatch_request
    rv = self.dispatch_request()
  File "/Library/Frameworks/Python.framework/Versions/3.7/lib/python3.7/site-packages/flask/app.py", line 1935, in dispatch_request
    return self.view_functions[rule.endpoint](**req.view_args)
  File "/Users/sergeykostitsin/MD5_service/server/flaskserv.py", line 48, in post
    return {'id': f'{task_id}'}
NameError: name 'task_id' is not defined
2019-12-14 13:41:18,669 127.0.0.1 - - [14/Dec/2019 13:41:18] "GET /submit?url=https://sun9-24.userapi.com/c840132/v840132969/40916/Tr3HbZNuvbY.jpg HTTP/1.1" 500 -
2019-12-14 13:41:18,883 Exception on /submit [GET]
Traceback (most recent call last):
  File "/Library/Frameworks/Python.framework/Versions/3.7/lib/python3.7/site-packages/flask/app.py", line 2446, in wsgi_app
    response = self.full_dispatch_request()
  File "/Library/Frameworks/Python.framework/Versions/3.7/lib/python3.7/site-packages/flask/app.py", line 1951, in full_dispatch_request
    rv = self.handle_user_exception(e)
  File "/Library/Frameworks/Python.framework/Versions/3.7/lib/python3.7/site-packages/flask/app.py", line 1820, in handle_user_exception
    reraise(exc_type, exc_value, tb)
  File "/Library/Frameworks/Python.framework/Versions/3.7/lib/python3.7/site-packages/flask/_compat.py", line 39, in reraise
    raise value
  File "/Library/Frameworks/Python.framework/Versions/3.7/lib/python3.7/site-packages/flask/app.py", line 1949, in full_dispatch_request
    rv = self.dispatch_request()
  File "/Library/Frameworks/Python.framework/Versions/3.7/lib/python3.7/site-packages/flask/app.py", line 1935, in dispatch_request
    return self.view_functions[rule.endpoint](**req.view_args)
  File "/Users/sergeykostitsin/MD5_service/server/flaskserv.py", line 48, in post
    return {'id': f'{task_id}'}
NameError: name 'task_id' is not defined
2019-12-14 13:41:18,884 127.0.0.1 - - [14/Dec/2019 13:41:18] "GET /submit?url=https://sun9-24.userapi.com/c840132/v840132969/40916/Tr3HbZNuvbY.jpg HTTP/1.1" 500 -
2019-12-14 13:41:19,082 Exception on /submit [GET]
Traceback (most recent call last):
  File "/Library/Frameworks/Python.framework/Versions/3.7/lib/python3.7/site-packages/flask/app.py", line 2446, in wsgi_app
    response = self.full_dispatch_request()
  File "/Library/Frameworks/Python.framework/Versions/3.7/lib/python3.7/site-packages/flask/app.py", line 1951, in full_dispatch_request
    rv = self.handle_user_exception(e)
  File "/Library/Frameworks/Python.framework/Versions/3.7/lib/python3.7/site-packages/flask/app.py", line 1820, in handle_user_exception
    reraise(exc_type, exc_value, tb)
  File "/Library/Frameworks/Python.framework/Versions/3.7/lib/python3.7/site-packages/flask/_compat.py", line 39, in reraise
    raise value
  File "/Library/Frameworks/Python.framework/Versions/3.7/lib/python3.7/site-packages/flask/app.py", line 1949, in full_dispatch_request
    rv = self.dispatch_request()
  File "/Library/Frameworks/Python.framework/Versions/3.7/lib/python3.7/site-packages/flask/app.py", line 1935, in dispatch_request
    return self.view_functions[rule.endpoint](**req.view_args)
  File "/Users/sergeykostitsin/MD5_service/server/flaskserv.py", line 48, in post
    return {'id': f'{task_id}'}
NameError: name 'task_id' is not defined
2019-12-14 13:41:19,082 127.0.0.1 - - [14/Dec/2019 13:41:19] "GET /submit?url=https://sun9-24.userapi.com/c840132/v840132969/40916/Tr3HbZNuvbY.jpg HTTP/1.1" 500 -
2019-12-14 13:41:19,313 Exception on /submit [GET]
Traceback (most recent call last):
  File "/Library/Frameworks/Python.framework/Versions/3.7/lib/python3.7/site-packages/flask/app.py", line 2446, in wsgi_app
    response = self.full_dispatch_request()
  File "/Library/Frameworks/Python.framework/Versions/3.7/lib/python3.7/site-packages/flask/app.py", line 1951, in full_dispatch_request
    rv = self.handle_user_exception(e)
  File "/Library/Frameworks/Python.framework/Versions/3.7/lib/python3.7/site-packages/flask/app.py", line 1820, in handle_user_exception
    reraise(exc_type, exc_value, tb)
  File "/Library/Frameworks/Python.framework/Versions/3.7/lib/python3.7/site-packages/flask/_compat.py", line 39, in reraise
    raise value
  File "/Library/Frameworks/Python.framework/Versions/3.7/lib/python3.7/site-packages/flask/app.py", line 1949, in full_dispatch_request
    rv = self.dispatch_request()
  File "/Library/Frameworks/Python.framework/Versions/3.7/lib/python3.7/site-packages/flask/app.py", line 1935, in dispatch_request
    return self.view_functions[rule.endpoint](**req.view_args)
  File "/Users/sergeykostitsin/MD5_service/server/flaskserv.py", line 48, in post
    return {'id': f'{task_id}'}
NameError: name 'task_id' is not defined
2019-12-14 13:41:19,313 127.0.0.1 - - [14/Dec/2019 13:41:19] "GET /submit?url=https://sun9-24.userapi.com/c840132/v840132969/40916/Tr3HbZNuvbY.jpg HTTP/1.1" 500 -
2019-12-14 13:42:14,714  * Running on http://127.0.0.1:5000/ (Press CTRL+C to quit)
2019-12-14 13:42:15,981 127.0.0.1 - - [14/Dec/2019 13:42:15] "GET /submit?url=https://sun9-24.userapi.com/c840132/v840132969/40916/Tr3HbZNuvbY.jpg HTTP/1.1" 200 -
2019-12-14 13:42:17,150 127.0.0.1 - - [14/Dec/2019 13:42:17] "GET /submit?url=https://sun9-24.userapi.com/c840132/v840132969/40916/Tr3HbZNuvbY.jpg HTTP/1.1" 200 -
2019-12-14 13:42:59,303  * Running on http://127.0.0.1:5000/ (Press CTRL+C to quit)
2019-12-14 13:43:00,066 127.0.0.1 - - [14/Dec/2019 13:43:00] "GET /submit?url=https://sun9-24.userapi.com/c840132/v840132969/40916/Tr3HbZNuvbY.jpg HTTP/1.1" 200 -
2019-12-14 13:43:14,219 1233
2019-12-14 13:43:14,399  * Running on http://127.0.0.1:5000/ (Press CTRL+C to quit)
2019-12-14 13:43:16,413 127.0.0.1 - - [14/Dec/2019 13:43:16] "GET /submit?url=https://sun9-24.userapi.com/c840132/v840132969/40916/Tr3HbZNuvbY.jpg HTTP/1.1" 200 -
2019-12-14 13:43:49,913 127.0.0.1 - - [14/Dec/2019 13:43:49] "GET /submit?url=https://sun9-24.userapi.com/c840132/v840132969/40916/Tr3HbZNuvbY.jpg HTTP/1.1" 200 -
2019-12-14 13:44:12,721  * Running on http://127.0.0.1:5000/ (Press CTRL+C to quit)
2019-12-14 13:44:14,132 1233
2019-12-14 13:44:14,282 127.0.0.1 - - [14/Dec/2019 13:44:14] "GET /submit?url=https://sun9-24.userapi.com/c840132/v840132969/40916/Tr3HbZNuvbY.jpg HTTP/1.1" 200 -
2019-12-14 13:53:58,293  * Running on http://127.0.0.1:5000/ (Press CTRL+C to quit)
2019-12-14 13:54:04,523 1233
2019-12-14 13:54:04,688 127.0.0.1 - - [14/Dec/2019 13:54:04] "GET /submit?url=https://sun9-24.userapi.com/c840132/v840132969/40916/Tr3HbZNuvbY.jpg HTTP/1.1" 200 -
2019-12-14 13:54:53,808  * Running on http://127.0.0.1:5000/ (Press CTRL+C to quit)
2019-12-14 13:54:59,255 1233
2019-12-14 13:54:59,394 127.0.0.1 - - [14/Dec/2019 13:54:59] "GET /submit?url=https://sun9-24.userapi.com/c840132/v840132969/40916/Tr3HbZNuvbY.jpg HTTP/1.1" 200 -
2019-12-14 13:56:15,530  * Running on http://127.0.0.1:5000/ (Press CTRL+C to quit)
2019-12-14 13:56:21,188 1233
2019-12-14 13:56:21,350 127.0.0.1 - - [14/Dec/2019 13:56:21] "GET /submit?url=https://sun9-24.userapi.com/c840132/v840132969/40916/Tr3HbZNuvbY.jpg HTTP/1.1" 200 -
2019-12-14 13:57:28,854  * Running on http://127.0.0.1:5000/ (Press CTRL+C to quit)
2019-12-14 13:57:33,975 1233
2019-12-14 13:57:34,177 127.0.0.1 - - [14/Dec/2019 13:57:34] "GET /submit?url=https://sun9-24.userapi.com/c840132/v840132969/40916/Tr3HbZNuvbY.jpg HTTP/1.1" 200 -
2019-12-14 13:59:24,105  * Running on http://127.0.0.1:5000/ (Press CTRL+C to quit)
2019-12-14 13:59:32,289 1233
2019-12-14 13:59:32,459 127.0.0.1 - - [14/Dec/2019 13:59:32] "GET /submit?url=https://sun9-24.userapi.com/c840132/v840132969/40916/Tr3HbZNuvbY.jpg HTTP/1.1" 200 -
2019-12-14 13:59:34,586 1233
2019-12-14 13:59:34,588 127.0.0.1 - - [14/Dec/2019 13:59:34] "GET /submit?url=https://sun9-24.userapi.com/c840132/v840132969/40916/Tr3HbZNuvbY.jpg HTTP/1.1" 200 -
2019-12-14 14:00:28,331  * Running on http://127.0.0.1:5000/ (Press CTRL+C to quit)
2019-12-14 14:00:36,931 1233
2019-12-14 14:00:37,109 127.0.0.1 - - [14/Dec/2019 14:00:37] "GET /submit?url=https://sun9-24.userapi.com/c840132/v840132969/40916/Tr3HbZNuvbY.jpg HTTP/1.1" 200 -
2019-12-14 14:02:24,015  * Running on http://127.0.0.1:5000/ (Press CTRL+C to quit)
2019-12-14 14:02:33,273 1233
2019-12-14 14:02:33,399 127.0.0.1 - - [14/Dec/2019 14:02:33] "GET /submit?url=https://sun9-24.userapi.com/c840132/v840132969/40916/Tr3HbZNuvbY.jpg HTTP/1.1" 200 -
2019-12-14 18:27:08,875  * Running on http://127.0.0.1:5000/ (Press CTRL+C to quit)
2019-12-14 18:27:12,624 after
2019-12-14 18:27:12,634 127.0.0.1 - - [14/Dec/2019 18:27:12] "GET /submit?url=https://sun9-24.userapi.com/c840132/v840132969/40916/Tr3HbZNuvbY.jpg HTTP/1.1" 200 -
2019-12-14 18:34:23,743  * Running on http://127.0.0.1:5000/ (Press CTRL+C to quit)
2019-12-14 18:37:39,042  * Running on http://127.0.0.1:5000/ (Press CTRL+C to quit)
2019-12-14 18:37:43,018 Exception on /submit [GET]
Traceback (most recent call last):
  File "/Library/Frameworks/Python.framework/Versions/3.7/lib/python3.7/site-packages/flask/app.py", line 2446, in wsgi_app
    response = self.full_dispatch_request()
  File "/Library/Frameworks/Python.framework/Versions/3.7/lib/python3.7/site-packages/flask/app.py", line 1951, in full_dispatch_request
    rv = self.handle_user_exception(e)
  File "/Library/Frameworks/Python.framework/Versions/3.7/lib/python3.7/site-packages/flask/app.py", line 1820, in handle_user_exception
    reraise(exc_type, exc_value, tb)
  File "/Library/Frameworks/Python.framework/Versions/3.7/lib/python3.7/site-packages/flask/_compat.py", line 39, in reraise
    raise value
  File "/Library/Frameworks/Python.framework/Versions/3.7/lib/python3.7/site-packages/flask/app.py", line 1949, in full_dispatch_request
    rv = self.dispatch_request()
  File "/Library/Frameworks/Python.framework/Versions/3.7/lib/python3.7/site-packages/flask/app.py", line 1935, in dispatch_request
    return self.view_functions[rule.endpoint](**req.view_args)
  File "/Users/sergeykostitsin/MD5_service/server/flaskserv.py", line 37, in post
    task_id = create_task_with_id(url,email)
  File "/Users/sergeykostitsin/MD5_service/server/flaskserv.py", line 42, in create_task_with_id
    task = calc_hash_sum.delay(url,mail)
  File "/Library/Frameworks/Python.framework/Versions/3.7/lib/python3.7/site-packages/celery/app/task.py", line 427, in delay
    return self.apply_async(args, kwargs)
  File "/Library/Frameworks/Python.framework/Versions/3.7/lib/python3.7/site-packages/celery/app/task.py", line 532, in apply_async
    check_arguments(*(args or ()), **(kwargs or {}))
TypeError: calc_hash_sum() takes from 1 to 2 positional arguments but 3 were given
2019-12-14 18:37:43,023 127.0.0.1 - - [14/Dec/2019 18:37:43] "GET /submit?url=https://sun9-24.userapi.com/c840132/v840132969/40916/Tr3HbZNuvbY.jpg HTTP/1.1" 500 -
2019-12-14 18:38:19,388  * Running on http://127.0.0.1:5000/ (Press CTRL+C to quit)
2019-12-14 18:38:24,758 after
2019-12-14 18:38:24,810 127.0.0.1 - - [14/Dec/2019 18:38:24] "GET /submit?url=https://sun9-24.userapi.com/c840132/v840132969/40916/Tr3HbZNuvbY.jpg HTTP/1.1" 200 -
2019-12-14 18:46:03,220  * Running on http://127.0.0.1:5000/ (Press CTRL+C to quit)
2019-12-14 18:46:11,719 after
2019-12-14 18:46:11,769 127.0.0.1 - - [14/Dec/2019 18:46:11] "GET /submit?url=https://sun9-24.userapi.com/c840132/v840132969/40916/Tr3HbZNuvbY.jpg HTTP/1.1" 200 -
2019-12-14 18:52:15,821  * Running on http://127.0.0.1:5000/ (Press CTRL+C to quit)
2019-12-14 18:52:20,698 after
2019-12-14 18:52:20,704 127.0.0.1 - - [14/Dec/2019 18:52:20] "GET /submit?url=https://sun9-24.userapi.com/c840132/v840132969/40916/Tr3HbZNuvbY.jpg HTTP/1.1" 200 -
2019-12-14 19:03:46,764  * Running on http://127.0.0.1:5000/ (Press CTRL+C to quit)
2019-12-14 19:03:54,183 after
2019-12-14 19:03:54,219 127.0.0.1 - - [14/Dec/2019 19:03:54] "GET /submit?url=https://sun9-24.userapi.com/c840132/v840132969/40916/Tr3HbZNuvbY.jpg HTTP/1.1" 200 -
2019-12-14 19:14:19,820  * Running on http://127.0.0.1:5000/ (Press CTRL+C to quit)
2019-12-14 19:14:28,754 after
2019-12-14 19:14:28,803 127.0.0.1 - - [14/Dec/2019 19:14:28] "GET /submit?url=https://sun9-24.userapi.com/c840132/v840132969/40916/Tr3HbZNuvbY.jpg HTTP/1.1" 200 -
2019-12-14 19:19:49,518  * Running on http://127.0.0.1:5000/ (Press CTRL+C to quit)
2019-12-14 19:19:55,685 127.0.0.1 - - [14/Dec/2019 19:19:55] "GET /submit?url=https://sun9-24.userapi.com/c840132/v840132969/40916/Tr3HbZNuvbY.jpg HTTP/1.1" 200 -
2019-12-14 19:25:12,021  * Running on http://127.0.0.1:5000/ (Press CTRL+C to quit)
2019-12-14 19:25:18,261 127.0.0.1 - - [14/Dec/2019 19:25:18] "GET /submit?url=https://sun9-24.userapi.com/c840132/v840132969/40916/Tr3HbZNuvbY.jpg HTTP/1.1" 200 -
2019-12-14 19:30:43,361  * Running on http://127.0.0.1:5000/ (Press CTRL+C to quit)
2019-12-14 19:30:52,744 127.0.0.1 - - [14/Dec/2019 19:30:52] "GET /submit?url=https://sun9-24.userapi.com/c840132/v840132969/40916/Tr3HbZNuvbY.jpg HTTP/1.1" 200 -
2019-12-14 19:30:59,278 127.0.0.1 - - [14/Dec/2019 19:30:59] "GET /submit?url=https://sun9-24.userapi.com/c840132/v840132969/40916/Tr3HbZNuvbY.jpg HTTP/1.1" 200 -
2019-12-14 19:59:23,052  * Running on http://127.0.0.1:5000/ (Press CTRL+C to quit)
2019-12-14 19:59:27,204 127.0.0.1 - - [14/Dec/2019 19:59:27] "GET /submit?url=https://sun9-24.userapi.com/c840132/v840132969/96316/Tr3HbZNuvbY.jpg HTTP/1.1" 200 -
2019-12-14 19:59:27,236 127.0.0.1 - - [14/Dec/2019 19:59:27] "GET /favicon.ico HTTP/1.1" 404 -
2019-12-14 20:01:13,975  * Running on http://127.0.0.1:5000/ (Press CTRL+C to quit)
2019-12-14 20:01:17,675 127.0.0.1 - - [14/Dec/2019 20:01:17] "GET /submit?url=https://sun9-69.userapi.com/c824201/v824201969/17341f/IfCwbiGRL7c.jpg HTTP/1.1" 200 -
2019-12-14 20:02:34,563  * Running on http://127.0.0.1:5000/ (Press CTRL+C to quit)
2019-12-14 20:02:38,092 127.0.0.1 - - [14/Dec/2019 20:02:38] "GET /submit?url=https://lol HTTP/1.1" 200 -
2019-12-14 20:02:38,120 127.0.0.1 - - [14/Dec/2019 20:02:38] "GET /favicon.ico HTTP/1.1" 404 -
2019-12-14 20:04:52,552  * Running on http://127.0.0.1:5000/ (Press CTRL+C to quit)
2019-12-14 20:04:56,260 127.0.0.1 - - [14/Dec/2019 20:04:56] "GET /submit?url=https://sun9-69.userapi.com/c82808981/v824209/173f/IfCwbL7c.jpg HTTP/1.1" 200 -
2019-12-14 20:04:56,503 127.0.0.1 - - [14/Dec/2019 20:04:56] "GET /favicon.ico HTTP/1.1" 404 -
2019-12-14 21:29:06,919  * Running on http://127.0.0.1:5000/ (Press CTRL+C to quit)
2019-12-14 21:30:16,349 127.0.0.1 - - [14/Dec/2019 21:30:16] "GET /submit?url=https://sun9-69.userapi.com/c824201/v824201969/17341f/IfCwbiGRL7c.jpg%22%27 HTTP/1.1" 200 -
2019-12-14 21:30:16,727 127.0.0.1 - - [14/Dec/2019 21:30:16] "GET /submit HTTP/1.1" 200 -
2019-12-14 21:30:17,547 127.0.0.1 - - [14/Dec/2019 21:30:17] "GET / HTTP/1.1" 404 -
2019-12-14 21:30:18,203 127.0.0.1 - - [14/Dec/2019 21:30:18] "GET /check?id=2 HTTP/1.1" 200 -
2019-12-14 21:30:28,717 127.0.0.1 - - [14/Dec/2019 21:30:28] "GET /check?id=08f55e6d-f811-4834-b78f-6577afc73db0 HTTP/1.1" 200 -
2019-12-14 21:30:28,842 127.0.0.1 - - [14/Dec/2019 21:30:28] "GET /favicon.ico HTTP/1.1" 404 -
2019-12-14 21:41:12,197  * Running on http://127.0.0.1:5000/ (Press CTRL+C to quit)
2019-12-14 21:41:19,220 {'id': '08f55e6d-f811-4834-b78f-6577afc73db0', 'md5': 'd98221d5899b371dcafc5dd2c9c9ffe1', 'status': '200', 'url': 'https://sun9-69.userapi.com/c824201/v824201969/17341f/IfCwbiGRL7c.jpg'}
2019-12-14 21:41:19,220 127.0.0.1 - - [14/Dec/2019 21:41:19] "GET /check?id=08f55e6d-f811-4834-b78f-6577afc73db0 HTTP/1.1" 200 -
2019-12-14 21:59:15,247  * Running on http://127.0.0.1:5000/ (Press CTRL+C to quit)
2019-12-14 21:59:20,491 Exception on /check [GET]
Traceback (most recent call last):
  File "/Library/Frameworks/Python.framework/Versions/3.7/lib/python3.7/site-packages/flask/app.py", line 2446, in wsgi_app
    response = self.full_dispatch_request()
  File "/Library/Frameworks/Python.framework/Versions/3.7/lib/python3.7/site-packages/flask/app.py", line 1951, in full_dispatch_request
    rv = self.handle_user_exception(e)
  File "/Library/Frameworks/Python.framework/Versions/3.7/lib/python3.7/site-packages/flask/app.py", line 1820, in handle_user_exception
    reraise(exc_type, exc_value, tb)
  File "/Library/Frameworks/Python.framework/Versions/3.7/lib/python3.7/site-packages/flask/_compat.py", line 39, in reraise
    raise value
  File "/Library/Frameworks/Python.framework/Versions/3.7/lib/python3.7/site-packages/flask/app.py", line 1949, in full_dispatch_request
    rv = self.dispatch_request()
  File "/Library/Frameworks/Python.framework/Versions/3.7/lib/python3.7/site-packages/flask/app.py", line 1935, in dispatch_request
    return self.view_functions[rule.endpoint](**req.view_args)
  File "/Users/sergeykostitsin/MD5_service/server/flaskserv.py", line 28, in get
    response = response_preparation(task_info)
  File "/Users/sergeykostitsin/MD5_service/server/flaskserv.py", line 61, in response_preparation
    if response['status'] == '200':
  File "/Library/Frameworks/Python.framework/Versions/3.7/lib/python3.7/site-packages/pymongo/cursor.py", line 618, in __getitem__
    "instances" % index)
TypeError: index 'status' cannot be applied to Cursor instances
2019-12-14 21:59:20,494 127.0.0.1 - - [14/Dec/2019 21:59:20] "GET /check?id=08f55e6d-f811-4834-b78f-6577afc73db0 HTTP/1.1" 500 -
2019-12-14 22:07:35,070  * Running on http://127.0.0.1:5000/ (Press CTRL+C to quit)
2019-12-14 22:07:41,373 Exception on /check [GET]
Traceback (most recent call last):
  File "/Library/Frameworks/Python.framework/Versions/3.7/lib/python3.7/site-packages/flask/app.py", line 2446, in wsgi_app
    response = self.full_dispatch_request()
  File "/Library/Frameworks/Python.framework/Versions/3.7/lib/python3.7/site-packages/flask/app.py", line 1951, in full_dispatch_request
    rv = self.handle_user_exception(e)
  File "/Library/Frameworks/Python.framework/Versions/3.7/lib/python3.7/site-packages/flask/app.py", line 1820, in handle_user_exception
    reraise(exc_type, exc_value, tb)
  File "/Library/Frameworks/Python.framework/Versions/3.7/lib/python3.7/site-packages/flask/_compat.py", line 39, in reraise
    raise value
  File "/Library/Frameworks/Python.framework/Versions/3.7/lib/python3.7/site-packages/flask/app.py", line 1949, in full_dispatch_request
    rv = self.dispatch_request()
  File "/Library/Frameworks/Python.framework/Versions/3.7/lib/python3.7/site-packages/flask/app.py", line 1935, in dispatch_request
    return self.view_functions[rule.endpoint](**req.view_args)
  File "/Users/sergeykostitsin/MD5_service/server/flaskserv.py", line 28, in get
    response = response_preparation(task_info)
  File "/Users/sergeykostitsin/MD5_service/server/flaskserv.py", line 61, in response_preparation
    if response.find({'status'}) == '200':
AttributeError: 'Cursor' object has no attribute 'find'
2019-12-14 22:07:41,376 127.0.0.1 - - [14/Dec/2019 22:07:41] "GET /check?id=08f55e6d-f811-4834-b78f-6577afc73db0 HTTP/1.1" 500 -
2019-12-14 22:16:28,746  * Running on http://127.0.0.1:5000/ (Press CTRL+C to quit)
2019-12-14 22:22:42,585  * Running on http://127.0.0.1:5000/ (Press CTRL+C to quit)
2019-12-14 22:22:47,963 Exception on /check [GET]
Traceback (most recent call last):
  File "/Library/Frameworks/Python.framework/Versions/3.7/lib/python3.7/site-packages/flask/app.py", line 2446, in wsgi_app
    response = self.full_dispatch_request()
  File "/Library/Frameworks/Python.framework/Versions/3.7/lib/python3.7/site-packages/flask/app.py", line 1951, in full_dispatch_request
    rv = self.handle_user_exception(e)
  File "/Library/Frameworks/Python.framework/Versions/3.7/lib/python3.7/site-packages/flask/app.py", line 1820, in handle_user_exception
    reraise(exc_type, exc_value, tb)
  File "/Library/Frameworks/Python.framework/Versions/3.7/lib/python3.7/site-packages/flask/_compat.py", line 39, in reraise
    raise value
  File "/Library/Frameworks/Python.framework/Versions/3.7/lib/python3.7/site-packages/flask/app.py", line 1949, in full_dispatch_request
    rv = self.dispatch_request()
  File "/Library/Frameworks/Python.framework/Versions/3.7/lib/python3.7/site-packages/flask/app.py", line 1935, in dispatch_request
    return self.view_functions[rule.endpoint](**req.view_args)
  File "/Users/sergeykostitsin/MD5_service/server/flaskserv.py", line 28, in get
    response = response_preparation(task_info)
  File "/Users/sergeykostitsin/MD5_service/server/flaskserv.py", line 62, in response_preparation
    for key, value in response:
ValueError: too many values to unpack (expected 2)
2019-12-14 22:22:47,965 127.0.0.1 - - [14/Dec/2019 22:22:47] "GET /check?id=08f55e6d-f811-4834-b78f-6577afc73db0 HTTP/1.1" 500 -
2019-12-14 22:26:17,967  * Running on http://127.0.0.1:5000/ (Press CTRL+C to quit)
2019-12-14 22:26:29,847 Exception on /check [GET]
Traceback (most recent call last):
  File "/Library/Frameworks/Python.framework/Versions/3.7/lib/python3.7/site-packages/flask/app.py", line 2446, in wsgi_app
    response = self.full_dispatch_request()
  File "/Library/Frameworks/Python.framework/Versions/3.7/lib/python3.7/site-packages/flask/app.py", line 1951, in full_dispatch_request
    rv = self.handle_user_exception(e)
  File "/Library/Frameworks/Python.framework/Versions/3.7/lib/python3.7/site-packages/flask/app.py", line 1820, in handle_user_exception
    reraise(exc_type, exc_value, tb)
  File "/Library/Frameworks/Python.framework/Versions/3.7/lib/python3.7/site-packages/flask/_compat.py", line 39, in reraise
    raise value
  File "/Library/Frameworks/Python.framework/Versions/3.7/lib/python3.7/site-packages/flask/app.py", line 1949, in full_dispatch_request
    rv = self.dispatch_request()
  File "/Library/Frameworks/Python.framework/Versions/3.7/lib/python3.7/site-packages/flask/app.py", line 1935, in dispatch_request
    return self.view_functions[rule.endpoint](**req.view_args)
  File "/Users/sergeykostitsin/MD5_service/server/flaskserv.py", line 28, in get
    response = response_preparation(task_info)
  File "/Users/sergeykostitsin/MD5_service/server/flaskserv.py", line 67, in response_preparation
    prepared_response = {'md5': response['md5'],
  File "/Library/Frameworks/Python.framework/Versions/3.7/lib/python3.7/site-packages/pymongo/cursor.py", line 579, in __getitem__
    self.__check_okay_to_chain()
  File "/Library/Frameworks/Python.framework/Versions/3.7/lib/python3.7/site-packages/pymongo/cursor.py", line 390, in __check_okay_to_chain
    raise InvalidOperation("cannot set options after executing query")
pymongo.errors.InvalidOperation: cannot set options after executing query
2019-12-14 22:26:29,851 127.0.0.1 - - [14/Dec/2019 22:26:29] "GET /check?id=08f55e6d-f811-4834-b78f-6577afc73db0 HTTP/1.1" 500 -
2019-12-14 22:28:49,957  * Running on http://127.0.0.1:5000/ (Press CTRL+C to quit)
2019-12-14 22:34:21,431  * Running on http://127.0.0.1:5000/ (Press CTRL+C to quit)
2019-12-14 22:34:27,818 Exception on /check [GET]
Traceback (most recent call last):
  File "/Library/Frameworks/Python.framework/Versions/3.7/lib/python3.7/site-packages/flask/app.py", line 2446, in wsgi_app
    response = self.full_dispatch_request()
  File "/Library/Frameworks/Python.framework/Versions/3.7/lib/python3.7/site-packages/flask/app.py", line 1951, in full_dispatch_request
    rv = self.handle_user_exception(e)
  File "/Library/Frameworks/Python.framework/Versions/3.7/lib/python3.7/site-packages/flask/app.py", line 1820, in handle_user_exception
    reraise(exc_type, exc_value, tb)
  File "/Library/Frameworks/Python.framework/Versions/3.7/lib/python3.7/site-packages/flask/_compat.py", line 39, in reraise
    raise value
  File "/Library/Frameworks/Python.framework/Versions/3.7/lib/python3.7/site-packages/flask/app.py", line 1949, in full_dispatch_request
    rv = self.dispatch_request()
  File "/Library/Frameworks/Python.framework/Versions/3.7/lib/python3.7/site-packages/flask/app.py", line 1935, in dispatch_request
    return self.view_functions[rule.endpoint](**req.view_args)
  File "/Users/sergeykostitsin/MD5_service/server/flaskserv.py", line 28, in get
    response = response_preparation(task_info)
  File "/Users/sergeykostitsin/MD5_service/server/flaskserv.py", line 66, in response_preparation
    prepared_response = {'md5': response['md5'],
  File "/Library/Frameworks/Python.framework/Versions/3.7/lib/python3.7/site-packages/pymongo/cursor.py", line 579, in __getitem__
    self.__check_okay_to_chain()
  File "/Library/Frameworks/Python.framework/Versions/3.7/lib/python3.7/site-packages/pymongo/cursor.py", line 390, in __check_okay_to_chain
    raise InvalidOperation("cannot set options after executing query")
pymongo.errors.InvalidOperation: cannot set options after executing query
2019-12-14 22:34:27,820 127.0.0.1 - - [14/Dec/2019 22:34:27] "GET /check?id=08f55e6d-f811-4834-b78f-6577afc73db0 HTTP/1.1" 500 -
2019-12-14 22:35:44,399  * Running on http://127.0.0.1:5000/ (Press CTRL+C to quit)
2019-12-14 22:35:46,078 [{'id': '08f55e6d-f811-4834-b78f-6577afc73db0', 'md5': 'd98221d5899b371dcafc5dd2c9c9ffe1', 'status': '200', 'url': 'https://sun9-69.userapi.com/c824201/v824201969/17341f/IfCwbiGRL7c.jpg'}]
2019-12-14 22:35:46,078 Exception on /check [GET]
Traceback (most recent call last):
  File "/Library/Frameworks/Python.framework/Versions/3.7/lib/python3.7/site-packages/flask/app.py", line 2446, in wsgi_app
    response = self.full_dispatch_request()
  File "/Library/Frameworks/Python.framework/Versions/3.7/lib/python3.7/site-packages/flask/app.py", line 1951, in full_dispatch_request
    rv = self.handle_user_exception(e)
  File "/Library/Frameworks/Python.framework/Versions/3.7/lib/python3.7/site-packages/flask/app.py", line 1820, in handle_user_exception
    reraise(exc_type, exc_value, tb)
  File "/Library/Frameworks/Python.framework/Versions/3.7/lib/python3.7/site-packages/flask/_compat.py", line 39, in reraise
    raise value
  File "/Library/Frameworks/Python.framework/Versions/3.7/lib/python3.7/site-packages/flask/app.py", line 1949, in full_dispatch_request
    rv = self.dispatch_request()
  File "/Library/Frameworks/Python.framework/Versions/3.7/lib/python3.7/site-packages/flask/app.py", line 1935, in dispatch_request
    return self.view_functions[rule.endpoint](**req.view_args)
  File "/Users/sergeykostitsin/MD5_service/server/flaskserv.py", line 28, in get
    response = response_preparation(task_info)
  File "/Users/sergeykostitsin/MD5_service/server/flaskserv.py", line 67, in response_preparation
    prepared_response = {'md5': response['md5'],
  File "/Library/Frameworks/Python.framework/Versions/3.7/lib/python3.7/site-packages/pymongo/cursor.py", line 579, in __getitem__
    self.__check_okay_to_chain()
  File "/Library/Frameworks/Python.framework/Versions/3.7/lib/python3.7/site-packages/pymongo/cursor.py", line 390, in __check_okay_to_chain
    raise InvalidOperation("cannot set options after executing query")
pymongo.errors.InvalidOperation: cannot set options after executing query
2019-12-14 22:35:46,081 127.0.0.1 - - [14/Dec/2019 22:35:46] "GET /check?id=08f55e6d-f811-4834-b78f-6577afc73db0 HTTP/1.1" 500 -
2019-12-14 22:36:33,622  * Running on http://127.0.0.1:5000/ (Press CTRL+C to quit)
2019-12-14 22:36:36,798 lol
2019-12-14 22:36:36,848 Exception on /check [GET]
Traceback (most recent call last):
  File "/Library/Frameworks/Python.framework/Versions/3.7/lib/python3.7/site-packages/flask/app.py", line 2446, in wsgi_app
    response = self.full_dispatch_request()
  File "/Library/Frameworks/Python.framework/Versions/3.7/lib/python3.7/site-packages/flask/app.py", line 1951, in full_dispatch_request
    rv = self.handle_user_exception(e)
  File "/Library/Frameworks/Python.framework/Versions/3.7/lib/python3.7/site-packages/flask/app.py", line 1820, in handle_user_exception
    reraise(exc_type, exc_value, tb)
  File "/Library/Frameworks/Python.framework/Versions/3.7/lib/python3.7/site-packages/flask/_compat.py", line 39, in reraise
    raise value
  File "/Library/Frameworks/Python.framework/Versions/3.7/lib/python3.7/site-packages/flask/app.py", line 1949, in full_dispatch_request
    rv = self.dispatch_request()
  File "/Library/Frameworks/Python.framework/Versions/3.7/lib/python3.7/site-packages/flask/app.py", line 1935, in dispatch_request
    return self.view_functions[rule.endpoint](**req.view_args)
  File "/Users/sergeykostitsin/MD5_service/server/flaskserv.py", line 28, in get
    response = response_preparation(task_info)
  File "/Users/sergeykostitsin/MD5_service/server/flaskserv.py", line 66, in response_preparation
    prepared_response = {'md5': response['md5'],
  File "/Library/Frameworks/Python.framework/Versions/3.7/lib/python3.7/site-packages/pymongo/cursor.py", line 579, in __getitem__
    self.__check_okay_to_chain()
  File "/Library/Frameworks/Python.framework/Versions/3.7/lib/python3.7/site-packages/pymongo/cursor.py", line 390, in __check_okay_to_chain
    raise InvalidOperation("cannot set options after executing query")
pymongo.errors.InvalidOperation: cannot set options after executing query
2019-12-14 22:36:36,851 127.0.0.1 - - [14/Dec/2019 22:36:36] "GET /check?id=08f55e6d-f811-4834-b78f-6577afc73db0 HTTP/1.1" 500 -
2019-12-14 22:37:33,661  * Running on http://127.0.0.1:5000/ (Press CTRL+C to quit)
2019-12-14 22:37:35,642 {'id': '08f55e6d-f811-4834-b78f-6577afc73db0', 'md5': 'd98221d5899b371dcafc5dd2c9c9ffe1', 'status': '200', 'url': 'https://sun9-69.userapi.com/c824201/v824201969/17341f/IfCwbiGRL7c.jpg'}
2019-12-14 22:37:35,642 Exception on /check [GET]
Traceback (most recent call last):
  File "/Library/Frameworks/Python.framework/Versions/3.7/lib/python3.7/site-packages/flask/app.py", line 2446, in wsgi_app
    response = self.full_dispatch_request()
  File "/Library/Frameworks/Python.framework/Versions/3.7/lib/python3.7/site-packages/flask/app.py", line 1951, in full_dispatch_request
    rv = self.handle_user_exception(e)
  File "/Library/Frameworks/Python.framework/Versions/3.7/lib/python3.7/site-packages/flask/app.py", line 1820, in handle_user_exception
    reraise(exc_type, exc_value, tb)
  File "/Library/Frameworks/Python.framework/Versions/3.7/lib/python3.7/site-packages/flask/_compat.py", line 39, in reraise
    raise value
  File "/Library/Frameworks/Python.framework/Versions/3.7/lib/python3.7/site-packages/flask/app.py", line 1949, in full_dispatch_request
    rv = self.dispatch_request()
  File "/Library/Frameworks/Python.framework/Versions/3.7/lib/python3.7/site-packages/flask/app.py", line 1935, in dispatch_request
    return self.view_functions[rule.endpoint](**req.view_args)
  File "/Users/sergeykostitsin/MD5_service/server/flaskserv.py", line 28, in get
    response = response_preparation(task_info)
  File "/Users/sergeykostitsin/MD5_service/server/flaskserv.py", line 66, in response_preparation
    prepared_response = {'md5': response['md5'],
  File "/Library/Frameworks/Python.framework/Versions/3.7/lib/python3.7/site-packages/pymongo/cursor.py", line 579, in __getitem__
    self.__check_okay_to_chain()
  File "/Library/Frameworks/Python.framework/Versions/3.7/lib/python3.7/site-packages/pymongo/cursor.py", line 390, in __check_okay_to_chain
    raise InvalidOperation("cannot set options after executing query")
pymongo.errors.InvalidOperation: cannot set options after executing query
2019-12-14 22:37:35,644 127.0.0.1 - - [14/Dec/2019 22:37:35] "GET /check?id=08f55e6d-f811-4834-b78f-6577afc73db0 HTTP/1.1" 500 -
2019-12-14 22:38:33,558  * Running on http://127.0.0.1:5000/ (Press CTRL+C to quit)
2019-12-14 22:38:49,690  * Running on http://127.0.0.1:5000/ (Press CTRL+C to quit)
2019-12-14 22:38:52,322 [{'id': '08f55e6d-f811-4834-b78f-6577afc73db0', 'md5': 'd98221d5899b371dcafc5dd2c9c9ffe1', 'status': '200', 'url': 'https://sun9-69.userapi.com/c824201/v824201969/17341f/IfCwbiGRL7c.jpg'}]
2019-12-14 22:38:52,322 {'id': '08f55e6d-f811-4834-b78f-6577afc73db0', 'md5': 'd98221d5899b371dcafc5dd2c9c9ffe1', 'status': '200', 'url': 'https://sun9-69.userapi.com/c824201/v824201969/17341f/IfCwbiGRL7c.jpg'}
2019-12-14 22:38:52,322 Exception on /check [GET]
Traceback (most recent call last):
  File "/Library/Frameworks/Python.framework/Versions/3.7/lib/python3.7/site-packages/flask/app.py", line 2446, in wsgi_app
    response = self.full_dispatch_request()
  File "/Library/Frameworks/Python.framework/Versions/3.7/lib/python3.7/site-packages/flask/app.py", line 1951, in full_dispatch_request
    rv = self.handle_user_exception(e)
  File "/Library/Frameworks/Python.framework/Versions/3.7/lib/python3.7/site-packages/flask/app.py", line 1820, in handle_user_exception
    reraise(exc_type, exc_value, tb)
  File "/Library/Frameworks/Python.framework/Versions/3.7/lib/python3.7/site-packages/flask/_compat.py", line 39, in reraise
    raise value
  File "/Library/Frameworks/Python.framework/Versions/3.7/lib/python3.7/site-packages/flask/app.py", line 1949, in full_dispatch_request
    rv = self.dispatch_request()
  File "/Library/Frameworks/Python.framework/Versions/3.7/lib/python3.7/site-packages/flask/app.py", line 1935, in dispatch_request
    return self.view_functions[rule.endpoint](**req.view_args)
  File "/Users/sergeykostitsin/MD5_service/server/flaskserv.py", line 28, in get
    response = response_preparation(task_info)
  File "/Users/sergeykostitsin/MD5_service/server/flaskserv.py", line 67, in response_preparation
    prepared_response = {'md5': response['md5'],
  File "/Library/Frameworks/Python.framework/Versions/3.7/lib/python3.7/site-packages/pymongo/cursor.py", line 579, in __getitem__
    self.__check_okay_to_chain()
  File "/Library/Frameworks/Python.framework/Versions/3.7/lib/python3.7/site-packages/pymongo/cursor.py", line 390, in __check_okay_to_chain
    raise InvalidOperation("cannot set options after executing query")
pymongo.errors.InvalidOperation: cannot set options after executing query
2019-12-14 22:38:52,326 127.0.0.1 - - [14/Dec/2019 22:38:52] "GET /check?id=08f55e6d-f811-4834-b78f-6577afc73db0 HTTP/1.1" 500 -
2019-12-14 22:40:09,221  * Running on http://127.0.0.1:5000/ (Press CTRL+C to quit)
2019-12-14 22:40:10,967 {'id': '08f55e6d-f811-4834-b78f-6577afc73db0', 'md5': 'd98221d5899b371dcafc5dd2c9c9ffe1', 'status': '200', 'url': 'https://sun9-69.userapi.com/c824201/v824201969/17341f/IfCwbiGRL7c.jpg'}
2019-12-14 22:40:10,968 Exception on /check [GET]
Traceback (most recent call last):
  File "/Library/Frameworks/Python.framework/Versions/3.7/lib/python3.7/site-packages/flask/app.py", line 2446, in wsgi_app
    response = self.full_dispatch_request()
  File "/Library/Frameworks/Python.framework/Versions/3.7/lib/python3.7/site-packages/flask/app.py", line 1951, in full_dispatch_request
    rv = self.handle_user_exception(e)
  File "/Library/Frameworks/Python.framework/Versions/3.7/lib/python3.7/site-packages/flask/app.py", line 1820, in handle_user_exception
    reraise(exc_type, exc_value, tb)
  File "/Library/Frameworks/Python.framework/Versions/3.7/lib/python3.7/site-packages/flask/_compat.py", line 39, in reraise
    raise value
  File "/Library/Frameworks/Python.framework/Versions/3.7/lib/python3.7/site-packages/flask/app.py", line 1949, in full_dispatch_request
    rv = self.dispatch_request()
  File "/Library/Frameworks/Python.framework/Versions/3.7/lib/python3.7/site-packages/flask/app.py", line 1935, in dispatch_request
    return self.view_functions[rule.endpoint](**req.view_args)
  File "/Users/sergeykostitsin/MD5_service/server/flaskserv.py", line 28, in get
    response = response_preparation(task_info)
  File "/Users/sergeykostitsin/MD5_service/server/flaskserv.py", line 67, in response_preparation
    prepared_response = {'md5': response['md5'],
  File "/Library/Frameworks/Python.framework/Versions/3.7/lib/python3.7/site-packages/pymongo/cursor.py", line 579, in __getitem__
    self.__check_okay_to_chain()
  File "/Library/Frameworks/Python.framework/Versions/3.7/lib/python3.7/site-packages/pymongo/cursor.py", line 390, in __check_okay_to_chain
    raise InvalidOperation("cannot set options after executing query")
pymongo.errors.InvalidOperation: cannot set options after executing query
2019-12-14 22:40:10,970 127.0.0.1 - - [14/Dec/2019 22:40:10] "GET /check?id=08f55e6d-f811-4834-b78f-6577afc73db0 HTTP/1.1" 500 -
2019-12-14 22:42:00,417  * Running on http://127.0.0.1:5000/ (Press CTRL+C to quit)
2019-12-14 22:42:03,274 127.0.0.1 - - [14/Dec/2019 22:42:03] "GET /check?id=08f55e6d-f811-4834-b78f-6577afc73db0 HTTP/1.1" 200 -
2019-12-14 22:42:36,893 127.0.0.1 - - [14/Dec/2019 22:42:36] "GET /check?id=08f55e6d-f811-4834-b78f-6577afc73db0 HTTP/1.1" 200 -
2019-12-14 22:42:40,358 Exception on /check [GET]
Traceback (most recent call last):
  File "/Library/Frameworks/Python.framework/Versions/3.7/lib/python3.7/site-packages/flask/app.py", line 2446, in wsgi_app
    response = self.full_dispatch_request()
  File "/Library/Frameworks/Python.framework/Versions/3.7/lib/python3.7/site-packages/flask/app.py", line 1951, in full_dispatch_request
    rv = self.handle_user_exception(e)
  File "/Library/Frameworks/Python.framework/Versions/3.7/lib/python3.7/site-packages/flask/app.py", line 1820, in handle_user_exception
    reraise(exc_type, exc_value, tb)
  File "/Library/Frameworks/Python.framework/Versions/3.7/lib/python3.7/site-packages/flask/_compat.py", line 39, in reraise
    raise value
  File "/Library/Frameworks/Python.framework/Versions/3.7/lib/python3.7/site-packages/flask/app.py", line 1949, in full_dispatch_request
    rv = self.dispatch_request()
  File "/Library/Frameworks/Python.framework/Versions/3.7/lib/python3.7/site-packages/flask/app.py", line 1935, in dispatch_request
    return self.view_functions[rule.endpoint](**req.view_args)
  File "/Users/sergeykostitsin/MD5_service/server/flaskserv.py", line 28, in get
    response = response_preparation(task_info)
  File "/Users/sergeykostitsin/MD5_service/server/flaskserv.py", line 64, in response_preparation
    response = dict_list[0]
IndexError: list index out of range
2019-12-14 22:42:40,360 127.0.0.1 - - [14/Dec/2019 22:42:40] "GET /check?id=0 HTTP/1.1" 500 -
2019-12-14 22:42:40,718 Exception on /check [GET]
Traceback (most recent call last):
  File "/Library/Frameworks/Python.framework/Versions/3.7/lib/python3.7/site-packages/flask/app.py", line 2446, in wsgi_app
    response = self.full_dispatch_request()
  File "/Library/Frameworks/Python.framework/Versions/3.7/lib/python3.7/site-packages/flask/app.py", line 1951, in full_dispatch_request
    rv = self.handle_user_exception(e)
  File "/Library/Frameworks/Python.framework/Versions/3.7/lib/python3.7/site-packages/flask/app.py", line 1820, in handle_user_exception
    reraise(exc_type, exc_value, tb)
  File "/Library/Frameworks/Python.framework/Versions/3.7/lib/python3.7/site-packages/flask/_compat.py", line 39, in reraise
    raise value
  File "/Library/Frameworks/Python.framework/Versions/3.7/lib/python3.7/site-packages/flask/app.py", line 1949, in full_dispatch_request
    rv = self.dispatch_request()
  File "/Library/Frameworks/Python.framework/Versions/3.7/lib/python3.7/site-packages/flask/app.py", line 1935, in dispatch_request
    return self.view_functions[rule.endpoint](**req.view_args)
  File "/Users/sergeykostitsin/MD5_service/server/flaskserv.py", line 28, in get
    response = response_preparation(task_info)
  File "/Users/sergeykostitsin/MD5_service/server/flaskserv.py", line 64, in response_preparation
    response = dict_list[0]
IndexError: list index out of range
2019-12-14 22:42:40,719 127.0.0.1 - - [14/Dec/2019 22:42:40] "GET /check?id=2 HTTP/1.1" 500 -
2019-12-14 22:42:42,080 Exception on /check [GET]
Traceback (most recent call last):
  File "/Library/Frameworks/Python.framework/Versions/3.7/lib/python3.7/site-packages/flask/app.py", line 2446, in wsgi_app
    response = self.full_dispatch_request()
  File "/Library/Frameworks/Python.framework/Versions/3.7/lib/python3.7/site-packages/flask/app.py", line 1952, in full_dispatch_request
    return self.finalize_request(rv)
  File "/Library/Frameworks/Python.framework/Versions/3.7/lib/python3.7/site-packages/flask/app.py", line 1967, in finalize_request
    response = self.make_response(rv)
  File "/Library/Frameworks/Python.framework/Versions/3.7/lib/python3.7/site-packages/flask/app.py", line 2097, in make_response
    "The view function did not return a valid response. The"
TypeError: The view function did not return a valid response. The function either returned None or ended without a return statement.
2019-12-14 22:42:42,080 127.0.0.1 - - [14/Dec/2019 22:42:42] "GET /check?id=86c8bbd7-d472-4578-9ae9-6dd913dd325d HTTP/1.1" 500 -
2019-12-14 22:42:42,214 127.0.0.1 - - [14/Dec/2019 22:42:42] "GET /favicon.ico HTTP/1.1" 404 -
2019-12-14 22:43:23,515 Exception on /check [GET]
Traceback (most recent call last):
  File "/Library/Frameworks/Python.framework/Versions/3.7/lib/python3.7/site-packages/flask/app.py", line 2446, in wsgi_app
    response = self.full_dispatch_request()
  File "/Library/Frameworks/Python.framework/Versions/3.7/lib/python3.7/site-packages/flask/app.py", line 1952, in full_dispatch_request
    return self.finalize_request(rv)
  File "/Library/Frameworks/Python.framework/Versions/3.7/lib/python3.7/site-packages/flask/app.py", line 1967, in finalize_request
    response = self.make_response(rv)
  File "/Library/Frameworks/Python.framework/Versions/3.7/lib/python3.7/site-packages/flask/app.py", line 2097, in make_response
    "The view function did not return a valid response. The"
TypeError: The view function did not return a valid response. The function either returned None or ended without a return statement.
2019-12-14 22:43:23,515 127.0.0.1 - - [14/Dec/2019 22:43:23] "GET /check?id=86c8bbd7-d472-4578-9ae9-6dd913dd325d HTTP/1.1" 500 -
2019-12-14 22:43:59,030 127.0.0.1 - - [14/Dec/2019 22:43:59] "GET /check?id=13ebd84b-a2b4-42b0-b1e6-66cf48ab0e1d HTTP/1.1" 200 -
2019-12-14 22:43:59,161 127.0.0.1 - - [14/Dec/2019 22:43:59] "GET /favicon.ico HTTP/1.1" 404 -
2019-12-14 22:44:28,016 127.0.0.1 - - [14/Dec/2019 22:44:28] "GET /check?id=13ebd84b-a2b4-42b0-b1e6-66cf48ab0e1d HTTP/1.1" 200 -
2019-12-14 22:44:31,526 Exception on /check [GET]
Traceback (most recent call last):
  File "/Library/Frameworks/Python.framework/Versions/3.7/lib/python3.7/site-packages/flask/app.py", line 2446, in wsgi_app
    response = self.full_dispatch_request()
  File "/Library/Frameworks/Python.framework/Versions/3.7/lib/python3.7/site-packages/flask/app.py", line 1951, in full_dispatch_request
    rv = self.handle_user_exception(e)
  File "/Library/Frameworks/Python.framework/Versions/3.7/lib/python3.7/site-packages/flask/app.py", line 1820, in handle_user_exception
    reraise(exc_type, exc_value, tb)
  File "/Library/Frameworks/Python.framework/Versions/3.7/lib/python3.7/site-packages/flask/_compat.py", line 39, in reraise
    raise value
  File "/Library/Frameworks/Python.framework/Versions/3.7/lib/python3.7/site-packages/flask/app.py", line 1949, in full_dispatch_request
    rv = self.dispatch_request()
  File "/Library/Frameworks/Python.framework/Versions/3.7/lib/python3.7/site-packages/flask/app.py", line 1935, in dispatch_request
    return self.view_functions[rule.endpoint](**req.view_args)
  File "/Users/sergeykostitsin/MD5_service/server/flaskserv.py", line 28, in get
    response = response_preparation(task_info)
  File "/Users/sergeykostitsin/MD5_service/server/flaskserv.py", line 64, in response_preparation
    response = dict_list[0]
IndexError: list index out of range
2019-12-14 22:44:31,527 127.0.0.1 - - [14/Dec/2019 22:44:31] "GET /check?id=1 HTTP/1.1" 500 -
2019-12-14 22:44:31,821 Exception on /check [GET]
Traceback (most recent call last):
  File "/Library/Frameworks/Python.framework/Versions/3.7/lib/python3.7/site-packages/flask/app.py", line 2446, in wsgi_app
    response = self.full_dispatch_request()
  File "/Library/Frameworks/Python.framework/Versions/3.7/lib/python3.7/site-packages/flask/app.py", line 1951, in full_dispatch_request
    rv = self.handle_user_exception(e)
  File "/Library/Frameworks/Python.framework/Versions/3.7/lib/python3.7/site-packages/flask/app.py", line 1820, in handle_user_exception
    reraise(exc_type, exc_value, tb)
  File "/Library/Frameworks/Python.framework/Versions/3.7/lib/python3.7/site-packages/flask/_compat.py", line 39, in reraise
    raise value
  File "/Library/Frameworks/Python.framework/Versions/3.7/lib/python3.7/site-packages/flask/app.py", line 1949, in full_dispatch_request
    rv = self.dispatch_request()
  File "/Library/Frameworks/Python.framework/Versions/3.7/lib/python3.7/site-packages/flask/app.py", line 1935, in dispatch_request
    return self.view_functions[rule.endpoint](**req.view_args)
  File "/Users/sergeykostitsin/MD5_service/server/flaskserv.py", line 28, in get
    response = response_preparation(task_info)
  File "/Users/sergeykostitsin/MD5_service/server/flaskserv.py", line 64, in response_preparation
    response = dict_list[0]
IndexError: list index out of range
2019-12-14 22:44:31,822 127.0.0.1 - - [14/Dec/2019 22:44:31] "GET /check?id=2 HTTP/1.1" 500 -
2019-12-14 22:44:32,505 Exception on /check [GET]
Traceback (most recent call last):
  File "/Library/Frameworks/Python.framework/Versions/3.7/lib/python3.7/site-packages/flask/app.py", line 2446, in wsgi_app
    response = self.full_dispatch_request()
  File "/Library/Frameworks/Python.framework/Versions/3.7/lib/python3.7/site-packages/flask/app.py", line 1952, in full_dispatch_request
    return self.finalize_request(rv)
  File "/Library/Frameworks/Python.framework/Versions/3.7/lib/python3.7/site-packages/flask/app.py", line 1967, in finalize_request
    response = self.make_response(rv)
  File "/Library/Frameworks/Python.framework/Versions/3.7/lib/python3.7/site-packages/flask/app.py", line 2097, in make_response
    "The view function did not return a valid response. The"
TypeError: The view function did not return a valid response. The function either returned None or ended without a return statement.
2019-12-14 22:44:32,507 127.0.0.1 - - [14/Dec/2019 22:44:32] "GET /check?id=86c8bbd7-d472-4578-9ae9-6dd913dd325d HTTP/1.1" 500 -
2019-12-14 22:44:33,188 Exception on /check [GET]
Traceback (most recent call last):
  File "/Library/Frameworks/Python.framework/Versions/3.7/lib/python3.7/site-packages/flask/app.py", line 2446, in wsgi_app
    response = self.full_dispatch_request()
  File "/Library/Frameworks/Python.framework/Versions/3.7/lib/python3.7/site-packages/flask/app.py", line 1952, in full_dispatch_request
    return self.finalize_request(rv)
  File "/Library/Frameworks/Python.framework/Versions/3.7/lib/python3.7/site-packages/flask/app.py", line 1967, in finalize_request
    response = self.make_response(rv)
  File "/Library/Frameworks/Python.framework/Versions/3.7/lib/python3.7/site-packages/flask/app.py", line 2097, in make_response
    "The view function did not return a valid response. The"
TypeError: The view function did not return a valid response. The function either returned None or ended without a return statement.
2019-12-14 22:44:33,189 127.0.0.1 - - [14/Dec/2019 22:44:33] "GET /check?id=86c8bbd7-d472-4578-9ae9-6dd913dd325d HTTP/1.1" 500 -
2019-12-14 22:45:48,723 Exception on /check [GET]
Traceback (most recent call last):
  File "/Library/Frameworks/Python.framework/Versions/3.7/lib/python3.7/site-packages/flask/app.py", line 2446, in wsgi_app
    response = self.full_dispatch_request()
  File "/Library/Frameworks/Python.framework/Versions/3.7/lib/python3.7/site-packages/flask/app.py", line 1952, in full_dispatch_request
    return self.finalize_request(rv)
  File "/Library/Frameworks/Python.framework/Versions/3.7/lib/python3.7/site-packages/flask/app.py", line 1967, in finalize_request
    response = self.make_response(rv)
  File "/Library/Frameworks/Python.framework/Versions/3.7/lib/python3.7/site-packages/flask/app.py", line 2097, in make_response
    "The view function did not return a valid response. The"
TypeError: The view function did not return a valid response. The function either returned None or ended without a return statement.
2019-12-14 22:45:48,724 127.0.0.1 - - [14/Dec/2019 22:45:48] "GET /check?id=86c8bbd7-d472-4578-9ae9-6dd913dd325d HTTP/1.1" 500 -
2019-12-14 22:45:52,434 Exception on /check [GET]
Traceback (most recent call last):
  File "/Library/Frameworks/Python.framework/Versions/3.7/lib/python3.7/site-packages/flask/app.py", line 2446, in wsgi_app
    response = self.full_dispatch_request()
  File "/Library/Frameworks/Python.framework/Versions/3.7/lib/python3.7/site-packages/flask/app.py", line 1951, in full_dispatch_request
    rv = self.handle_user_exception(e)
  File "/Library/Frameworks/Python.framework/Versions/3.7/lib/python3.7/site-packages/flask/app.py", line 1820, in handle_user_exception
    reraise(exc_type, exc_value, tb)
  File "/Library/Frameworks/Python.framework/Versions/3.7/lib/python3.7/site-packages/flask/_compat.py", line 39, in reraise
    raise value
  File "/Library/Frameworks/Python.framework/Versions/3.7/lib/python3.7/site-packages/flask/app.py", line 1949, in full_dispatch_request
    rv = self.dispatch_request()
  File "/Library/Frameworks/Python.framework/Versions/3.7/lib/python3.7/site-packages/flask/app.py", line 1935, in dispatch_request
    return self.view_functions[rule.endpoint](**req.view_args)
  File "/Users/sergeykostitsin/MD5_service/server/flaskserv.py", line 28, in get
    response = response_preparation(task_info)
  File "/Users/sergeykostitsin/MD5_service/server/flaskserv.py", line 64, in response_preparation
    response = dict_list[0]
IndexError: list index out of range
2019-12-14 22:45:52,435 127.0.0.1 - - [14/Dec/2019 22:45:52] "GET /check?id=2 HTTP/1.1" 500 -
2019-12-14 22:45:53,195 Exception on /check [GET]
Traceback (most recent call last):
  File "/Library/Frameworks/Python.framework/Versions/3.7/lib/python3.7/site-packages/flask/app.py", line 2446, in wsgi_app
    response = self.full_dispatch_request()
  File "/Library/Frameworks/Python.framework/Versions/3.7/lib/python3.7/site-packages/flask/app.py", line 1952, in full_dispatch_request
    return self.finalize_request(rv)
  File "/Library/Frameworks/Python.framework/Versions/3.7/lib/python3.7/site-packages/flask/app.py", line 1967, in finalize_request
    response = self.make_response(rv)
  File "/Library/Frameworks/Python.framework/Versions/3.7/lib/python3.7/site-packages/flask/app.py", line 2097, in make_response
    "The view function did not return a valid response. The"
TypeError: The view function did not return a valid response. The function either returned None or ended without a return statement.
2019-12-14 22:45:53,196 127.0.0.1 - - [14/Dec/2019 22:45:53] "GET /check?id=86c8bbd7-d472-4578-9ae9-6dd913dd325d HTTP/1.1" 500 -
2019-12-14 22:45:53,996 Exception on /check [GET]
Traceback (most recent call last):
  File "/Library/Frameworks/Python.framework/Versions/3.7/lib/python3.7/site-packages/flask/app.py", line 2446, in wsgi_app
    response = self.full_dispatch_request()
  File "/Library/Frameworks/Python.framework/Versions/3.7/lib/python3.7/site-packages/flask/app.py", line 1952, in full_dispatch_request
    return self.finalize_request(rv)
  File "/Library/Frameworks/Python.framework/Versions/3.7/lib/python3.7/site-packages/flask/app.py", line 1967, in finalize_request
    response = self.make_response(rv)
  File "/Library/Frameworks/Python.framework/Versions/3.7/lib/python3.7/site-packages/flask/app.py", line 2097, in make_response
    "The view function did not return a valid response. The"
TypeError: The view function did not return a valid response. The function either returned None or ended without a return statement.
2019-12-14 22:45:53,997 127.0.0.1 - - [14/Dec/2019 22:45:53] "GET /check?id=86c8bbd7-d472-4578-9ae9-6dd913dd325d HTTP/1.1" 500 -
2019-12-14 22:46:35,475  * Running on http://127.0.0.1:5000/ (Press CTRL+C to quit)
2019-12-14 22:46:37,811 127.0.0.1 - - [14/Dec/2019 22:46:37] "GET /check?id=86c8bbd7-d472-4578-9ae9-6dd913dd325d HTTP/1.1" 200 -
2019-12-14 22:50:35,728  * Running on http://127.0.0.1:5000/ (Press CTRL+C to quit)
2019-12-14 22:50:41,786 Exception on /check [GET]
Traceback (most recent call last):
  File "/Library/Frameworks/Python.framework/Versions/3.7/lib/python3.7/site-packages/flask/app.py", line 2446, in wsgi_app
    response = self.full_dispatch_request()
  File "/Library/Frameworks/Python.framework/Versions/3.7/lib/python3.7/site-packages/flask/app.py", line 1951, in full_dispatch_request
    rv = self.handle_user_exception(e)
  File "/Library/Frameworks/Python.framework/Versions/3.7/lib/python3.7/site-packages/flask/app.py", line 1820, in handle_user_exception
    reraise(exc_type, exc_value, tb)
  File "/Library/Frameworks/Python.framework/Versions/3.7/lib/python3.7/site-packages/flask/_compat.py", line 39, in reraise
    raise value
  File "/Library/Frameworks/Python.framework/Versions/3.7/lib/python3.7/site-packages/flask/app.py", line 1949, in full_dispatch_request
    rv = self.dispatch_request()
  File "/Library/Frameworks/Python.framework/Versions/3.7/lib/python3.7/site-packages/flask/app.py", line 1935, in dispatch_request
    return self.view_functions[rule.endpoint](**req.view_args)
  File "/Users/sergeykostitsin/MD5_service/server/flaskserv.py", line 28, in get
    response = response_preparation(task_info)
  File "/Users/sergeykostitsin/MD5_service/server/flaskserv.py", line 60, in response_preparation
    response = dict_list[0]
IndexError: list index out of range
2019-12-14 22:50:41,788 127.0.0.1 - - [14/Dec/2019 22:50:41] "GET /check?id=2 HTTP/1.1" 500 -
2019-12-14 22:50:42,385 Exception on /check [GET]
Traceback (most recent call last):
  File "/Library/Frameworks/Python.framework/Versions/3.7/lib/python3.7/site-packages/flask/app.py", line 2446, in wsgi_app
    response = self.full_dispatch_request()
  File "/Library/Frameworks/Python.framework/Versions/3.7/lib/python3.7/site-packages/flask/app.py", line 1951, in full_dispatch_request
    rv = self.handle_user_exception(e)
  File "/Library/Frameworks/Python.framework/Versions/3.7/lib/python3.7/site-packages/flask/app.py", line 1820, in handle_user_exception
    reraise(exc_type, exc_value, tb)
  File "/Library/Frameworks/Python.framework/Versions/3.7/lib/python3.7/site-packages/flask/_compat.py", line 39, in reraise
    raise value
  File "/Library/Frameworks/Python.framework/Versions/3.7/lib/python3.7/site-packages/flask/app.py", line 1949, in full_dispatch_request
    rv = self.dispatch_request()
  File "/Library/Frameworks/Python.framework/Versions/3.7/lib/python3.7/site-packages/flask/app.py", line 1935, in dispatch_request
    return self.view_functions[rule.endpoint](**req.view_args)
  File "/Users/sergeykostitsin/MD5_service/server/flaskserv.py", line 28, in get
    response = response_preparation(task_info)
  File "/Users/sergeykostitsin/MD5_service/server/flaskserv.py", line 60, in response_preparation
    response = dict_list[0]
IndexError: list index out of range
2019-12-14 22:50:42,386 127.0.0.1 - - [14/Dec/2019 22:50:42] "GET /check HTTP/1.1" 500 -
2019-12-14 22:50:42,523 127.0.0.1 - - [14/Dec/2019 22:50:42] "GET /favicon.ico HTTP/1.1" 404 -
2019-12-14 22:50:46,430 Exception on /check [GET]
Traceback (most recent call last):
  File "/Library/Frameworks/Python.framework/Versions/3.7/lib/python3.7/site-packages/flask/app.py", line 2446, in wsgi_app
    response = self.full_dispatch_request()
  File "/Library/Frameworks/Python.framework/Versions/3.7/lib/python3.7/site-packages/flask/app.py", line 1951, in full_dispatch_request
    rv = self.handle_user_exception(e)
  File "/Library/Frameworks/Python.framework/Versions/3.7/lib/python3.7/site-packages/flask/app.py", line 1820, in handle_user_exception
    reraise(exc_type, exc_value, tb)
  File "/Library/Frameworks/Python.framework/Versions/3.7/lib/python3.7/site-packages/flask/_compat.py", line 39, in reraise
    raise value
  File "/Library/Frameworks/Python.framework/Versions/3.7/lib/python3.7/site-packages/flask/app.py", line 1949, in full_dispatch_request
    rv = self.dispatch_request()
  File "/Library/Frameworks/Python.framework/Versions/3.7/lib/python3.7/site-packages/flask/app.py", line 1935, in dispatch_request
    return self.view_functions[rule.endpoint](**req.view_args)
  File "/Users/sergeykostitsin/MD5_service/server/flaskserv.py", line 28, in get
    response = response_preparation(task_info)
  File "/Users/sergeykostitsin/MD5_service/server/flaskserv.py", line 60, in response_preparation
    response = dict_list[0]
IndexError: list index out of range
2019-12-14 22:50:46,431 127.0.0.1 - - [14/Dec/2019 22:50:46] "GET /check?id=2 HTTP/1.1" 500 -
2019-12-14 22:50:46,770 Exception on /check [GET]
Traceback (most recent call last):
  File "/Library/Frameworks/Python.framework/Versions/3.7/lib/python3.7/site-packages/flask/app.py", line 2446, in wsgi_app
    response = self.full_dispatch_request()
  File "/Library/Frameworks/Python.framework/Versions/3.7/lib/python3.7/site-packages/flask/app.py", line 1951, in full_dispatch_request
    rv = self.handle_user_exception(e)
  File "/Library/Frameworks/Python.framework/Versions/3.7/lib/python3.7/site-packages/flask/app.py", line 1820, in handle_user_exception
    reraise(exc_type, exc_value, tb)
  File "/Library/Frameworks/Python.framework/Versions/3.7/lib/python3.7/site-packages/flask/_compat.py", line 39, in reraise
    raise value
  File "/Library/Frameworks/Python.framework/Versions/3.7/lib/python3.7/site-packages/flask/app.py", line 1949, in full_dispatch_request
    rv = self.dispatch_request()
  File "/Library/Frameworks/Python.framework/Versions/3.7/lib/python3.7/site-packages/flask/app.py", line 1935, in dispatch_request
    return self.view_functions[rule.endpoint](**req.view_args)
  File "/Users/sergeykostitsin/MD5_service/server/flaskserv.py", line 28, in get
    response = response_preparation(task_info)
  File "/Users/sergeykostitsin/MD5_service/server/flaskserv.py", line 60, in response_preparation
    response = dict_list[0]
IndexError: list index out of range
2019-12-14 22:50:46,771 127.0.0.1 - - [14/Dec/2019 22:50:46] "GET /check HTTP/1.1" 500 -
2019-12-14 22:50:46,893 127.0.0.1 - - [14/Dec/2019 22:50:46] "GET /favicon.ico HTTP/1.1" 404 -
2019-12-14 22:51:00,602  * Running on http://127.0.0.1:5000/ (Press CTRL+C to quit)
2019-12-14 22:51:04,009 Exception on /check [GET]
Traceback (most recent call last):
  File "/Library/Frameworks/Python.framework/Versions/3.7/lib/python3.7/site-packages/flask/app.py", line 2446, in wsgi_app
    response = self.full_dispatch_request()
  File "/Library/Frameworks/Python.framework/Versions/3.7/lib/python3.7/site-packages/flask/app.py", line 1951, in full_dispatch_request
    rv = self.handle_user_exception(e)
  File "/Library/Frameworks/Python.framework/Versions/3.7/lib/python3.7/site-packages/flask/app.py", line 1820, in handle_user_exception
    reraise(exc_type, exc_value, tb)
  File "/Library/Frameworks/Python.framework/Versions/3.7/lib/python3.7/site-packages/flask/_compat.py", line 39, in reraise
    raise value
  File "/Library/Frameworks/Python.framework/Versions/3.7/lib/python3.7/site-packages/flask/app.py", line 1949, in full_dispatch_request
    rv = self.dispatch_request()
  File "/Library/Frameworks/Python.framework/Versions/3.7/lib/python3.7/site-packages/flask/app.py", line 1935, in dispatch_request
    return self.view_functions[rule.endpoint](**req.view_args)
  File "/Users/sergeykostitsin/MD5_service/server/flaskserv.py", line 28, in get
    response = response_preparation(task_info)
  File "/Users/sergeykostitsin/MD5_service/server/flaskserv.py", line 60, in response_preparation
    response = dict_list[0]
IndexError: list index out of range
2019-12-14 22:51:04,012 127.0.0.1 - - [14/Dec/2019 22:51:04] "GET /check HTTP/1.1" 500 -
2019-12-14 22:51:45,404  * Running on http://127.0.0.1:5000/ (Press CTRL+C to quit)
2019-12-14 22:51:48,294 Exception on /check [GET]
Traceback (most recent call last):
  File "/Library/Frameworks/Python.framework/Versions/3.7/lib/python3.7/site-packages/flask/app.py", line 2446, in wsgi_app
    response = self.full_dispatch_request()
  File "/Library/Frameworks/Python.framework/Versions/3.7/lib/python3.7/site-packages/flask/app.py", line 1951, in full_dispatch_request
    rv = self.handle_user_exception(e)
  File "/Library/Frameworks/Python.framework/Versions/3.7/lib/python3.7/site-packages/flask/app.py", line 1820, in handle_user_exception
    reraise(exc_type, exc_value, tb)
  File "/Library/Frameworks/Python.framework/Versions/3.7/lib/python3.7/site-packages/flask/_compat.py", line 39, in reraise
    raise value
  File "/Library/Frameworks/Python.framework/Versions/3.7/lib/python3.7/site-packages/flask/app.py", line 1949, in full_dispatch_request
    rv = self.dispatch_request()
  File "/Library/Frameworks/Python.framework/Versions/3.7/lib/python3.7/site-packages/flask/app.py", line 1935, in dispatch_request
    return self.view_functions[rule.endpoint](**req.view_args)
  File "/Users/sergeykostitsin/MD5_service/server/flaskserv.py", line 28, in get
    response = response_preparation(task_info)
  File "/Users/sergeykostitsin/MD5_service/server/flaskserv.py", line 60, in response_preparation
    response = dict_list[0]
IndexError: list index out of range
2019-12-14 22:51:48,296 127.0.0.1 - - [14/Dec/2019 22:51:48] "GET /check HTTP/1.1" 500 -
2019-12-14 22:51:51,753 Exception on /check [GET]
Traceback (most recent call last):
  File "/Library/Frameworks/Python.framework/Versions/3.7/lib/python3.7/site-packages/flask/app.py", line 2446, in wsgi_app
    response = self.full_dispatch_request()
  File "/Library/Frameworks/Python.framework/Versions/3.7/lib/python3.7/site-packages/flask/app.py", line 1951, in full_dispatch_request
    rv = self.handle_user_exception(e)
  File "/Library/Frameworks/Python.framework/Versions/3.7/lib/python3.7/site-packages/flask/app.py", line 1820, in handle_user_exception
    reraise(exc_type, exc_value, tb)
  File "/Library/Frameworks/Python.framework/Versions/3.7/lib/python3.7/site-packages/flask/_compat.py", line 39, in reraise
    raise value
  File "/Library/Frameworks/Python.framework/Versions/3.7/lib/python3.7/site-packages/flask/app.py", line 1949, in full_dispatch_request
    rv = self.dispatch_request()
  File "/Library/Frameworks/Python.framework/Versions/3.7/lib/python3.7/site-packages/flask/app.py", line 1935, in dispatch_request
    return self.view_functions[rule.endpoint](**req.view_args)
  File "/Users/sergeykostitsin/MD5_service/server/flaskserv.py", line 28, in get
    response = response_preparation(task_info)
  File "/Users/sergeykostitsin/MD5_service/server/flaskserv.py", line 60, in response_preparation
    response = dict_list[0]
IndexError: list index out of range
2019-12-14 22:51:51,754 127.0.0.1 - - [14/Dec/2019 22:51:51] "GET /check HTTP/1.1" 500 -
2019-12-14 22:51:52,934 Exception on /check [GET]
Traceback (most recent call last):
  File "/Library/Frameworks/Python.framework/Versions/3.7/lib/python3.7/site-packages/flask/app.py", line 2446, in wsgi_app
    response = self.full_dispatch_request()
  File "/Library/Frameworks/Python.framework/Versions/3.7/lib/python3.7/site-packages/flask/app.py", line 1951, in full_dispatch_request
    rv = self.handle_user_exception(e)
  File "/Library/Frameworks/Python.framework/Versions/3.7/lib/python3.7/site-packages/flask/app.py", line 1820, in handle_user_exception
    reraise(exc_type, exc_value, tb)
  File "/Library/Frameworks/Python.framework/Versions/3.7/lib/python3.7/site-packages/flask/_compat.py", line 39, in reraise
    raise value
  File "/Library/Frameworks/Python.framework/Versions/3.7/lib/python3.7/site-packages/flask/app.py", line 1949, in full_dispatch_request
    rv = self.dispatch_request()
  File "/Library/Frameworks/Python.framework/Versions/3.7/lib/python3.7/site-packages/flask/app.py", line 1935, in dispatch_request
    return self.view_functions[rule.endpoint](**req.view_args)
  File "/Users/sergeykostitsin/MD5_service/server/flaskserv.py", line 28, in get
    response = response_preparation(task_info)
  File "/Users/sergeykostitsin/MD5_service/server/flaskserv.py", line 60, in response_preparation
    response = dict_list[0]
IndexError: list index out of range
2019-12-14 22:51:52,935 127.0.0.1 - - [14/Dec/2019 22:51:52] "GET /check?id=2 HTTP/1.1" 500 -
2019-12-14 22:51:55,283 Exception on /check [GET]
Traceback (most recent call last):
  File "/Library/Frameworks/Python.framework/Versions/3.7/lib/python3.7/site-packages/flask/app.py", line 2446, in wsgi_app
    response = self.full_dispatch_request()
  File "/Library/Frameworks/Python.framework/Versions/3.7/lib/python3.7/site-packages/flask/app.py", line 1951, in full_dispatch_request
    rv = self.handle_user_exception(e)
  File "/Library/Frameworks/Python.framework/Versions/3.7/lib/python3.7/site-packages/flask/app.py", line 1820, in handle_user_exception
    reraise(exc_type, exc_value, tb)
  File "/Library/Frameworks/Python.framework/Versions/3.7/lib/python3.7/site-packages/flask/_compat.py", line 39, in reraise
    raise value
  File "/Library/Frameworks/Python.framework/Versions/3.7/lib/python3.7/site-packages/flask/app.py", line 1949, in full_dispatch_request
    rv = self.dispatch_request()
  File "/Library/Frameworks/Python.framework/Versions/3.7/lib/python3.7/site-packages/flask/app.py", line 1935, in dispatch_request
    return self.view_functions[rule.endpoint](**req.view_args)
  File "/Users/sergeykostitsin/MD5_service/server/flaskserv.py", line 28, in get
    response = response_preparation(task_info)
  File "/Users/sergeykostitsin/MD5_service/server/flaskserv.py", line 60, in response_preparation
    response = dict_list[0]
IndexError: list index out of range
2019-12-14 22:51:55,284 127.0.0.1 - - [14/Dec/2019 22:51:55] "GET /check?id= HTTP/1.1" 500 -
2019-12-14 22:51:55,411 127.0.0.1 - - [14/Dec/2019 22:51:55] "GET /favicon.ico HTTP/1.1" 404 -
2019-12-14 22:52:03,115 Exception on /check [GET]
Traceback (most recent call last):
  File "/Library/Frameworks/Python.framework/Versions/3.7/lib/python3.7/site-packages/flask/app.py", line 2446, in wsgi_app
    response = self.full_dispatch_request()
  File "/Library/Frameworks/Python.framework/Versions/3.7/lib/python3.7/site-packages/flask/app.py", line 1951, in full_dispatch_request
    rv = self.handle_user_exception(e)
  File "/Library/Frameworks/Python.framework/Versions/3.7/lib/python3.7/site-packages/flask/app.py", line 1820, in handle_user_exception
    reraise(exc_type, exc_value, tb)
  File "/Library/Frameworks/Python.framework/Versions/3.7/lib/python3.7/site-packages/flask/_compat.py", line 39, in reraise
    raise value
  File "/Library/Frameworks/Python.framework/Versions/3.7/lib/python3.7/site-packages/flask/app.py", line 1949, in full_dispatch_request
    rv = self.dispatch_request()
  File "/Library/Frameworks/Python.framework/Versions/3.7/lib/python3.7/site-packages/flask/app.py", line 1935, in dispatch_request
    return self.view_functions[rule.endpoint](**req.view_args)
  File "/Users/sergeykostitsin/MD5_service/server/flaskserv.py", line 28, in get
    response = response_preparation(task_info)
  File "/Users/sergeykostitsin/MD5_service/server/flaskserv.py", line 60, in response_preparation
    response = dict_list[0]
IndexError: list index out of range
2019-12-14 22:52:03,116 127.0.0.1 - - [14/Dec/2019 22:52:03] "GET /check?id=0 HTTP/1.1" 500 -
2019-12-14 22:52:03,629 Exception on /check [GET]
Traceback (most recent call last):
  File "/Library/Frameworks/Python.framework/Versions/3.7/lib/python3.7/site-packages/flask/app.py", line 2446, in wsgi_app
    response = self.full_dispatch_request()
  File "/Library/Frameworks/Python.framework/Versions/3.7/lib/python3.7/site-packages/flask/app.py", line 1951, in full_dispatch_request
    rv = self.handle_user_exception(e)
  File "/Library/Frameworks/Python.framework/Versions/3.7/lib/python3.7/site-packages/flask/app.py", line 1820, in handle_user_exception
    reraise(exc_type, exc_value, tb)
  File "/Library/Frameworks/Python.framework/Versions/3.7/lib/python3.7/site-packages/flask/_compat.py", line 39, in reraise
    raise value
  File "/Library/Frameworks/Python.framework/Versions/3.7/lib/python3.7/site-packages/flask/app.py", line 1949, in full_dispatch_request
    rv = self.dispatch_request()
  File "/Library/Frameworks/Python.framework/Versions/3.7/lib/python3.7/site-packages/flask/app.py", line 1935, in dispatch_request
    return self.view_functions[rule.endpoint](**req.view_args)
  File "/Users/sergeykostitsin/MD5_service/server/flaskserv.py", line 28, in get
    response = response_preparation(task_info)
  File "/Users/sergeykostitsin/MD5_service/server/flaskserv.py", line 60, in response_preparation
    response = dict_list[0]
IndexError: list index out of range
2019-12-14 22:52:03,630 127.0.0.1 - - [14/Dec/2019 22:52:03] "GET /check?id=0 HTTP/1.1" 500 -
2019-12-14 22:54:57,918  * Running on http://127.0.0.1:5000/ (Press CTRL+C to quit)
2019-12-14 22:55:02,101 Exception on /check [GET]
Traceback (most recent call last):
  File "/Library/Frameworks/Python.framework/Versions/3.7/lib/python3.7/site-packages/flask/app.py", line 2446, in wsgi_app
    response = self.full_dispatch_request()
  File "/Library/Frameworks/Python.framework/Versions/3.7/lib/python3.7/site-packages/flask/app.py", line 1951, in full_dispatch_request
    rv = self.handle_user_exception(e)
  File "/Library/Frameworks/Python.framework/Versions/3.7/lib/python3.7/site-packages/flask/app.py", line 1820, in handle_user_exception
    reraise(exc_type, exc_value, tb)
  File "/Library/Frameworks/Python.framework/Versions/3.7/lib/python3.7/site-packages/flask/_compat.py", line 39, in reraise
    raise value
  File "/Library/Frameworks/Python.framework/Versions/3.7/lib/python3.7/site-packages/flask/app.py", line 1949, in full_dispatch_request
    rv = self.dispatch_request()
  File "/Library/Frameworks/Python.framework/Versions/3.7/lib/python3.7/site-packages/flask/app.py", line 1935, in dispatch_request
    return self.view_functions[rule.endpoint](**req.view_args)
  File "/Users/sergeykostitsin/MD5_service/server/flaskserv.py", line 31, in get
    response = response_preparation(dict_list[0],task_info)
IndexError: list index out of range
2019-12-14 22:55:02,104 127.0.0.1 - - [14/Dec/2019 22:55:02] "GET /check?id=0 HTTP/1.1" 500 -
2019-12-14 22:57:35,329  * Running on http://127.0.0.1:5000/ (Press CTRL+C to quit)
2019-12-14 22:57:38,571 Exception on /check [GET]
Traceback (most recent call last):
  File "/Library/Frameworks/Python.framework/Versions/3.7/lib/python3.7/site-packages/flask/app.py", line 2446, in wsgi_app
    response = self.full_dispatch_request()
  File "/Library/Frameworks/Python.framework/Versions/3.7/lib/python3.7/site-packages/flask/app.py", line 1951, in full_dispatch_request
    rv = self.handle_user_exception(e)
  File "/Library/Frameworks/Python.framework/Versions/3.7/lib/python3.7/site-packages/flask/app.py", line 1820, in handle_user_exception
    reraise(exc_type, exc_value, tb)
  File "/Library/Frameworks/Python.framework/Versions/3.7/lib/python3.7/site-packages/flask/_compat.py", line 39, in reraise
    raise value
  File "/Library/Frameworks/Python.framework/Versions/3.7/lib/python3.7/site-packages/flask/app.py", line 1949, in full_dispatch_request
    rv = self.dispatch_request()
  File "/Library/Frameworks/Python.framework/Versions/3.7/lib/python3.7/site-packages/flask/app.py", line 1935, in dispatch_request
    return self.view_functions[rule.endpoint](**req.view_args)
  File "/Users/sergeykostitsin/MD5_service/server/flaskserv.py", line 28, in get
    response = response_preparation(task_info)
  File "/Users/sergeykostitsin/MD5_service/server/flaskserv.py", line 60, in response_preparation
    response = dict_list[0]
IndexError: list index out of range
2019-12-14 22:57:38,573 127.0.0.1 - - [14/Dec/2019 22:57:38] "GET /check?id= HTTP/1.1" 500 -
2019-12-14 22:57:39,191 Exception on /check [GET]
Traceback (most recent call last):
  File "/Library/Frameworks/Python.framework/Versions/3.7/lib/python3.7/site-packages/flask/app.py", line 2446, in wsgi_app
    response = self.full_dispatch_request()
  File "/Library/Frameworks/Python.framework/Versions/3.7/lib/python3.7/site-packages/flask/app.py", line 1951, in full_dispatch_request
    rv = self.handle_user_exception(e)
  File "/Library/Frameworks/Python.framework/Versions/3.7/lib/python3.7/site-packages/flask/app.py", line 1820, in handle_user_exception
    reraise(exc_type, exc_value, tb)
  File "/Library/Frameworks/Python.framework/Versions/3.7/lib/python3.7/site-packages/flask/_compat.py", line 39, in reraise
    raise value
  File "/Library/Frameworks/Python.framework/Versions/3.7/lib/python3.7/site-packages/flask/app.py", line 1949, in full_dispatch_request
    rv = self.dispatch_request()
  File "/Library/Frameworks/Python.framework/Versions/3.7/lib/python3.7/site-packages/flask/app.py", line 1935, in dispatch_request
    return self.view_functions[rule.endpoint](**req.view_args)
  File "/Users/sergeykostitsin/MD5_service/server/flaskserv.py", line 28, in get
    response = response_preparation(task_info)
  File "/Users/sergeykostitsin/MD5_service/server/flaskserv.py", line 60, in response_preparation
    response = dict_list[0]
IndexError: list index out of range
2019-12-14 22:57:39,192 127.0.0.1 - - [14/Dec/2019 22:57:39] "GET /check?id=1 HTTP/1.1" 500 -
2019-12-14 22:57:40,227 Exception on /check [GET]
Traceback (most recent call last):
  File "/Library/Frameworks/Python.framework/Versions/3.7/lib/python3.7/site-packages/flask/app.py", line 2446, in wsgi_app
    response = self.full_dispatch_request()
  File "/Library/Frameworks/Python.framework/Versions/3.7/lib/python3.7/site-packages/flask/app.py", line 1951, in full_dispatch_request
    rv = self.handle_user_exception(e)
  File "/Library/Frameworks/Python.framework/Versions/3.7/lib/python3.7/site-packages/flask/app.py", line 1820, in handle_user_exception
    reraise(exc_type, exc_value, tb)
  File "/Library/Frameworks/Python.framework/Versions/3.7/lib/python3.7/site-packages/flask/_compat.py", line 39, in reraise
    raise value
  File "/Library/Frameworks/Python.framework/Versions/3.7/lib/python3.7/site-packages/flask/app.py", line 1949, in full_dispatch_request
    rv = self.dispatch_request()
  File "/Library/Frameworks/Python.framework/Versions/3.7/lib/python3.7/site-packages/flask/app.py", line 1935, in dispatch_request
    return self.view_functions[rule.endpoint](**req.view_args)
  File "/Users/sergeykostitsin/MD5_service/server/flaskserv.py", line 28, in get
    response = response_preparation(task_info)
  File "/Users/sergeykostitsin/MD5_service/server/flaskserv.py", line 60, in response_preparation
    response = dict_list[0]
IndexError: list index out of range
2019-12-14 22:57:40,228 127.0.0.1 - - [14/Dec/2019 22:57:40] "GET /check?id=1234 HTTP/1.1" 500 -
2019-12-14 22:57:40,351 127.0.0.1 - - [14/Dec/2019 22:57:40] "GET /favicon.ico HTTP/1.1" 404 -
2019-12-14 23:00:39,675  * Running on http://127.0.0.1:5000/ (Press CTRL+C to quit)
2019-12-14 23:00:48,657 127.0.0.1 - - [14/Dec/2019 23:00:48] "GET /check?id=1234 HTTP/1.1" 200 -
2019-12-14 23:00:52,065 127.0.0.1 - - [14/Dec/2019 23:00:52] "GET /check?id=1234 HTTP/1.1" 200 -
2019-12-14 23:00:52,363 127.0.0.1 - - [14/Dec/2019 23:00:52] "GET /check?id=1 HTTP/1.1" 200 -
2019-12-14 23:00:52,989 127.0.0.1 - - [14/Dec/2019 23:00:52] "GET /check?id= HTTP/1.1" 200 -
2019-12-14 23:01:25,125 127.0.0.1 - - [14/Dec/2019 23:01:25] "GET /check?id=0 HTTP/1.1" 200 -
2019-12-14 23:01:25,580 127.0.0.1 - - [14/Dec/2019 23:01:25] "GET /check?id=0 HTTP/1.1" 200 -
2019-12-14 23:01:28,035 127.0.0.1 - - [14/Dec/2019 23:01:28] "GET /check?id= HTTP/1.1" 200 -
2019-12-14 23:01:28,957 127.0.0.1 - - [14/Dec/2019 23:01:28] "GET /check?id=1 HTTP/1.1" 200 -
2019-12-14 23:01:29,601 127.0.0.1 - - [14/Dec/2019 23:01:29] "GET /check?id=1 HTTP/1.1" 200 -
2019-12-14 23:01:32,809 127.0.0.1 - - [14/Dec/2019 23:01:32] "GET /check?id= HTTP/1.1" 200 -
2019-12-14 23:01:33,706 127.0.0.1 - - [14/Dec/2019 23:01:33] "GET /check?id= HTTP/1.1" 200 -
2019-12-14 23:01:35,552 127.0.0.1 - - [14/Dec/2019 23:01:35] "GET /check?id=2 HTTP/1.1" 200 -
2019-12-14 23:01:35,878 127.0.0.1 - - [14/Dec/2019 23:01:35] "GET /check HTTP/1.1" 200 -
2019-12-14 23:01:36,180 127.0.0.1 - - [14/Dec/2019 23:01:36] "GET /check HTTP/1.1" 200 -
2019-12-14 23:01:36,393 127.0.0.1 - - [14/Dec/2019 23:01:36] "GET /check HTTP/1.1" 200 -
2019-12-14 23:05:45,339 127.0.0.1 - - [14/Dec/2019 23:05:45] "GET /check HTTP/1.1" 200 -
2019-12-14 23:05:48,743 127.0.0.1 - - [14/Dec/2019 23:05:48] "GET /check?id=86c8bbd7-d472-4578-9ae9-6dd913dd325d HTTP/1.1" 200 -
2019-12-14 23:47:29,358 127.0.0.1 - - [14/Dec/2019 23:47:29] "POST /submit HTTP/1.1" 405 -
2019-12-14 23:49:04,803  * Running on http://127.0.0.1:5000/ (Press CTRL+C to quit)
2019-12-14 23:49:32,415 127.0.0.1 - - [14/Dec/2019 23:49:32] "POST /submit HTTP/1.1" 405 -
2019-12-14 23:49:56,696 127.0.0.1 - - [14/Dec/2019 23:49:56] "GET /check?id=86c8bbd7-d472-4578-9ae9-6dd913dd325d HTTP/1.1" 200 -
2019-12-14 23:50:45,019  * Running on http://127.0.0.1:5000/ (Press CTRL+C to quit)
2019-12-14 23:51:10,859 127.0.0.1 - - [14/Dec/2019 23:51:10] "GET /check?id=86c8bbd7-d472-4578-9ae9-6dd913dd325d HTTP/1.1" 200 -
2019-12-14 23:51:14,032 127.0.0.1 - - [14/Dec/2019 23:51:14] "GET /check?id= HTTP/1.1" 200 -
2019-12-14 23:51:14,627 127.0.0.1 - - [14/Dec/2019 23:51:14] "GET /check?id=2 HTTP/1.1" 200 -
2019-12-14 23:51:15,292 127.0.0.1 - - [14/Dec/2019 23:51:15] "GET / HTTP/1.1" 404 -
2019-12-14 23:51:15,872 127.0.0.1 - - [14/Dec/2019 23:51:15] "GET /submit HTTP/1.1" 405 -
2019-12-14 23:52:34,130 127.0.0.1 - - [14/Dec/2019 23:52:34] "POST /submit HTTP/1.1" 200 -
2019-12-15 01:17:47,962  * Running on http://127.0.0.1:5000/ (Press CTRL+C to quit)
2019-12-15 01:19:13,458 127.0.0.1 - - [15/Dec/2019 01:19:13] "POST /submit HTTP/1.1" 200 -
2019-12-15 01:22:16,818  * Running on http://127.0.0.1:5000/ (Press CTRL+C to quit)
2019-12-15 01:22:21,206 None
2019-12-15 01:22:21,206 None
2019-12-15 01:22:21,361 127.0.0.1 - - [15/Dec/2019 01:22:21] "POST /submit HTTP/1.1" 200 -
2019-12-15 01:24:28,889 None
2019-12-15 01:24:28,891 None
2019-12-15 01:24:28,941 127.0.0.1 - - [15/Dec/2019 01:24:28] "POST /submit HTTP/1.1" 200 -
2019-12-15 01:24:59,646 None
2019-12-15 01:24:59,646 None
2019-12-15 01:24:59,690 127.0.0.1 - - [15/Dec/2019 01:24:59] "POST /submit HTTP/1.1" 200 -
2019-12-15 01:25:55,723  * Running on http://127.0.0.1:5000/ (Press CTRL+C to quit)
2019-12-15 01:26:47,565 0e4fac17-f367
2019-12-15 01:26:47,621 127.0.0.1 - - [15/Dec/2019 01:26:47] "GET /check?id=0e4fac17-f367 HTTP/1.1" 200 -
2019-12-15 01:29:15,754  * Running on http://127.0.0.1:5000/ (Press CTRL+C to quit)
2019-12-15 01:29:29,944 None
2019-12-15 01:29:29,944 None
2019-12-15 01:29:30,086 127.0.0.1 - - [15/Dec/2019 01:29:30] "POST /submit HTTP/1.1" 200 -
2019-12-15 01:34:03,446  * Running on http://127.0.0.1:5000/ (Press CTRL+C to quit)
2019-12-15 01:34:10,823 127.0.0.1 - - [15/Dec/2019 01:34:10] "POST /submit HTTP/1.1" 400 -
2019-12-15 01:36:18,985  * Running on http://127.0.0.1:5000/ (Press CTRL+C to quit)
2019-12-15 01:36:28,963 127.0.0.1 - - [15/Dec/2019 01:36:28] "POST /submit HTTP/1.1" 400 -
2019-12-15 01:37:30,260 user@example.com
2019-12-15 01:37:30,260 http://site.com/file.txt
2019-12-15 01:37:30,409 127.0.0.1 - - [15/Dec/2019 01:37:30] "POST /submit HTTP/1.1" 200 -
2019-12-15 01:39:31,133  * Running on http://127.0.0.1:5000/ (Press CTRL+C to quit)
2019-12-15 01:39:37,470 None
2019-12-15 01:39:37,471 None
2019-12-15 01:39:37,616 127.0.0.1 - - [15/Dec/2019 01:39:37] "POST /submit HTTP/1.1" 200 -
2019-12-15 01:42:39,607  * Running on http://127.0.0.1:5000/ (Press CTRL+C to quit)
2019-12-15 01:42:44,558 None
2019-12-15 01:42:44,558 https://sun9-24.userapi.com/c840132/v840132969/40916/Tr3HbZNuvbY.jpg
2019-12-15 01:42:44,715 127.0.0.1 - - [15/Dec/2019 01:42:44] "POST /submit HTTP/1.1" 200 -
2019-12-15 01:43:23,832 s.kostitsin@bk.ru
2019-12-15 01:43:23,832 https://sun9-24.userapi.com/c840132/v840132969/40916/Tr3HbZNuvbY.jpg
2019-12-15 01:43:23,835 127.0.0.1 - - [15/Dec/2019 01:43:23] "POST /submit HTTP/1.1" 200 -
2019-12-15 01:46:13,201  * Running on http://127.0.0.1:5000/ (Press CTRL+C to quit)
2019-12-15 01:46:38,652  * Running on http://127.0.0.1:5000/ (Press CTRL+C to quit)
2019-12-15 01:46:46,957 s.kostitsin@bk.ru
2019-12-15 01:46:46,957 https://sun9-24.userapi.com/c840132/v840132969/40916/Tr3HbZNuvbY.jpg
2019-12-15 01:46:47,091 127.0.0.1 - - [15/Dec/2019 01:46:47] "POST /submit HTTP/1.1" 200 -
2019-12-15 01:47:59,313  * Running on http://127.0.0.1:5000/ (Press CTRL+C to quit)
2019-12-15 01:48:02,998 s.kostitsin@bk.ru
2019-12-15 01:48:02,999 https://sun9-24.userapi.com/c840132/v840132969/40916/Tr3HbZNuvbY.jpg
2019-12-15 01:48:03,144 127.0.0.1 - - [15/Dec/2019 01:48:03] "POST /submit HTTP/1.1" 200 -
2019-12-15 01:50:21,343  * Running on http://127.0.0.1:5000/ (Press CTRL+C to quit)
2019-12-15 01:50:24,620 s.kostitsin@bk.ru
2019-12-15 01:50:24,620 https://sun9-24.userapi.com/c840132/v840132969/40916/Tr3HbZNuvbY.jpg
2019-12-15 01:50:24,777 127.0.0.1 - - [15/Dec/2019 01:50:24] "POST /submit HTTP/1.1" 200 -
2019-12-15 01:53:29,251  * Running on http://127.0.0.1:5000/ (Press CTRL+C to quit)
2019-12-15 01:53:31,173 s.kostitsin@bk.ru
2019-12-15 01:53:31,174 https://sun9-24.userapi.com/c840132/v840132969/40916/Tr3HbZNuvbY.jpg
2019-12-15 01:53:31,319 127.0.0.1 - - [15/Dec/2019 01:53:31] "POST /submit HTTP/1.1" 200 -
2019-12-15 02:16:38,430  * Running on http://127.0.0.1:5000/ (Press CTRL+C to quit)
2019-12-15 02:16:44,190 s.kostitsin@bk.ru
2019-12-15 02:16:44,190 https://sun9-24.userapi.com/c840132/v840132969/40916/Tr3HbZNuvbY.jpg
2019-12-15 02:16:44,332 127.0.0.1 - - [15/Dec/2019 02:16:44] "POST /submit HTTP/1.1" 200 -
2019-12-15 02:32:45,283  * Running on http://127.0.0.1:5000/ (Press CTRL+C to quit)
2019-12-15 02:32:49,319 s.kostitsin@bk.ru
2019-12-15 02:32:49,319 https://sun9-24.userapi.com/c840132/v840132969/40916/Tr3HbZNuvbY.jpg
2019-12-15 02:32:49,503 127.0.0.1 - - [15/Dec/2019 02:32:49] "POST /submit HTTP/1.1" 200 -
2019-12-15 02:33:59,285  * Running on http://127.0.0.1:5000/ (Press CTRL+C to quit)
2019-12-15 02:34:02,559 s.kostitsin@bk.ru
2019-12-15 02:34:02,559 https://sun9-24.userapi.com/c840132/v840132969/40916/Tr3HbZNuvbY.jpg
2019-12-15 02:34:02,701 127.0.0.1 - - [15/Dec/2019 02:34:02] "POST /submit HTTP/1.1" 200 -
2019-12-15 02:37:22,356  * Running on http://127.0.0.1:5000/ (Press CTRL+C to quit)
2019-12-15 02:37:26,338 s.kostitsin@bk.ru
2019-12-15 02:37:26,338 https://sun9-24.userapi.com/c840132/v840132969/40916/Tr3HbZNuvbY.jpg
2019-12-15 02:37:26,493 127.0.0.1 - - [15/Dec/2019 02:37:26] "POST /submit HTTP/1.1" 200 -
2019-12-15 02:40:44,367  * Running on http://127.0.0.1:5000/ (Press CTRL+C to quit)
2019-12-15 02:40:46,087 s.kostitsin@bk.ru
2019-12-15 02:40:46,087 https://sun9-24.userapi.com/c840132/v840132969/40916/Tr3HbZNuvbY.jpg
2019-12-15 02:40:46,245 127.0.0.1 - - [15/Dec/2019 02:40:46] "POST /submit HTTP/1.1" 200 -
2019-12-15 02:46:07,852  * Running on http://127.0.0.1:5000/ (Press CTRL+C to quit)
2019-12-15 02:46:10,323 s.kostitsin@bk.ru
2019-12-15 02:46:10,323 https://sun9-24.userapi.com/c840132/v840132969/40916/Tr3HbZNuvbY.jpg
2019-12-15 02:46:10,465 127.0.0.1 - - [15/Dec/2019 02:46:10] "POST /submit HTTP/1.1" 200 -
2019-12-15 02:47:58,999  * Running on http://127.0.0.1:5000/ (Press CTRL+C to quit)
2019-12-15 02:48:00,525 s.kostitsin@bk.ru
2019-12-15 02:48:00,525 https://sun9-24.userapi.com/c840132/v840132969/40916/Tr3HbZNuvbY.jpg
2019-12-15 02:48:00,669 127.0.0.1 - - [15/Dec/2019 02:48:00] "POST /submit HTTP/1.1" 200 -
2019-12-15 02:59:19,780  * Running on http://127.0.0.1:5000/ (Press CTRL+C to quit)
2019-12-15 02:59:21,114 s.kostitsin@bk.ru
2019-12-15 02:59:21,115 https://sun9-24.userapi.com/c840132/v840132969/40916/Tr3HbZNuvbY.jpg
2019-12-15 02:59:21,276 127.0.0.1 - - [15/Dec/2019 02:59:21] "POST /submit HTTP/1.1" 200 -
2019-12-15 03:00:21,899  * Running on http://127.0.0.1:5000/ (Press CTRL+C to quit)
2019-12-15 03:00:24,334 s.kostitsin@bk.ru
2019-12-15 03:00:24,335 https://sun9-24.userapi.com/c840132/v840132969/40916/Tr3HbZNuvbY.jpg
2019-12-15 03:00:24,470 127.0.0.1 - - [15/Dec/2019 03:00:24] "POST /submit HTTP/1.1" 200 -
2019-12-15 03:01:57,093  * Running on http://127.0.0.1:5000/ (Press CTRL+C to quit)
2019-12-15 03:02:01,202 s.kostitsin@bk.ru
2019-12-15 03:02:01,202 https://sun9-24.userapi.com/c840132/v840132969/40916/Tr3HbZNuvbY.jpg
2019-12-15 03:02:01,343 127.0.0.1 - - [15/Dec/2019 03:02:01] "POST /submit HTTP/1.1" 200 -
2019-12-15 03:02:52,107  * Running on http://127.0.0.1:5000/ (Press CTRL+C to quit)
2019-12-15 03:02:54,359 s.kostitsin@bk.ru
2019-12-15 03:02:54,359 https://sun9-24.userapi.com/c840132/v840132969/40916/Tr3HbZNuvbY.jpg
2019-12-15 03:02:54,506 127.0.0.1 - - [15/Dec/2019 03:02:54] "POST /submit HTTP/1.1" 200 -
2019-12-15 03:04:24,251  * Running on http://127.0.0.1:5000/ (Press CTRL+C to quit)
2019-12-15 03:04:25,132 s.kostitsin@bk.ru
2019-12-15 03:04:25,132 https://sun9-24.userapi.com/c840132/v840132969/40916/Tr3HbZNuvbY.jpg
2019-12-15 03:04:25,268 127.0.0.1 - - [15/Dec/2019 03:04:25] "POST /submit HTTP/1.1" 200 -
2019-12-15 03:16:23,108  * Running on http://127.0.0.1:5000/ (Press CTRL+C to quit)
2019-12-15 03:16:24,951 s.kostitsin@bk.ru
2019-12-15 03:16:24,952 https://sun9-24.userapi.com/c840132/v840132969/40916/Tr3HbZNuvbY.jpg
2019-12-15 03:16:25,104 127.0.0.1 - - [15/Dec/2019 03:16:25] "POST /submit HTTP/1.1" 200 -
2019-12-15 03:17:02,906  * Running on http://127.0.0.1:5000/ (Press CTRL+C to quit)
2019-12-15 03:17:03,902 s.kostitsin@bk.ru
2019-12-15 03:17:03,903 https://sun9-24.userapi.com/c840132/v840132969/40916/Tr3HbZNuvbY.jpg
2019-12-15 03:17:04,042 127.0.0.1 - - [15/Dec/2019 03:17:04] "POST /submit HTTP/1.1" 200 -
2019-12-15 03:17:53,924  * Running on http://127.0.0.1:5000/ (Press CTRL+C to quit)
2019-12-15 03:17:55,325 s.kostitsin@bk.ru
2019-12-15 03:17:55,326 https://sun9-24.userapi.com/c840132/v840132969/40916/Tr3HbZNuvbY.jpg
2019-12-15 03:17:55,396 127.0.0.1 - - [15/Dec/2019 03:17:55] "POST /submit HTTP/1.1" 200 -
2019-12-15 03:18:50,964  * Running on http://127.0.0.1:5000/ (Press CTRL+C to quit)
2019-12-15 03:18:53,239 s.kostitsin@bk.ru
2019-12-15 03:18:53,239 https://sun9-24.userapi.com/c840132/v840132969/40916/Tr3HbZNuvbY.jpg
2019-12-15 03:18:53,308 127.0.0.1 - - [15/Dec/2019 03:18:53] "POST /submit HTTP/1.1" 200 -
2019-12-15 14:03:44,798  * Running on http://127.0.0.1:5000/ (Press CTRL+C to quit)
2019-12-15 14:04:02,970 s.kostitsin@bk.ru
2019-12-15 14:04:02,971 https://sun9-24.userapi.com/c840132/v840132969/40916/Tr3HbZNuvbY.jpg
2019-12-15 14:04:03,124 127.0.0.1 - - [15/Dec/2019 14:04:03] "POST /submit HTTP/1.1" 200 -
2019-12-15 14:05:22,972  * Running on http://127.0.0.1:5000/ (Press CTRL+C to quit)
2019-12-15 14:05:48,921 127.0.0.1 - - [15/Dec/2019 14:05:48] "GET /check?id=382277b4-7ab1-4ff0-97e3-ea6a6fc66fc2 HTTP/1.1" 200 -
2019-12-15 14:14:02,055  * Running on http://127.0.0.1:5000/ (Press CTRL+C to quit)
2019-12-15 14:14:09,443 s.kostitsin@bk.ru
2019-12-15 14:14:09,443 https://sun9-24.userapi.com/c840132/v840132969/40916/Tr3HbZNuvbY.jpg
2019-12-15 14:14:09,599 127.0.0.1 - - [15/Dec/2019 14:14:09] "POST /submit HTTP/1.1" 200 -
2019-12-15 14:16:56,772  * Running on http://127.0.0.1:5000/ (Press CTRL+C to quit)
2019-12-15 14:17:00,736 s.kostitsin@bk.ru
2019-12-15 14:17:00,736 https://sun9-24.userapi.com/c840132/v840132969/40916/Tr3HbZNuvbY.jpg
2019-12-15 14:17:00,880 127.0.0.1 - - [15/Dec/2019 14:17:00] "POST /submit HTTP/1.1" 200 -
2019-12-15 14:27:27,506  * Running on http://127.0.0.1:5000/ (Press CTRL+C to quit)
2019-12-15 14:27:39,191 s.kostitsin@bk.ru
2019-12-15 14:27:39,191 https://sun9-24.userapi.com/c840132/v840132969/40916/Tr3HbZNuvbY.jpg
2019-12-15 14:27:39,349 127.0.0.1 - - [15/Dec/2019 14:27:39] "POST /submit HTTP/1.1" 200 -
2019-12-15 14:28:37,423 127.0.0.1 - - [15/Dec/2019 14:28:37] "GET /check?id=e637d3c8-8793-4332-96a6-6619e679e003 HTTP/1.1" 200 -
2019-12-15 14:28:45,031 127.0.0.1 - - [15/Dec/2019 14:28:45] "GET /check?id=e63 HTTP/1.1" 200 -
2019-12-15 14:28:51,278 127.0.0.1 - - [15/Dec/2019 14:28:51] "GET /check HTTP/1.1" 200 -
2019-12-15 14:37:58,935  * Running on http://127.0.0.1:5000/ (Press CTRL+C to quit)
2019-12-15 16:11:52,174  * Running on http://127.0.0.1:5000/ (Press CTRL+C to quit)
2019-12-15 16:12:07,036 s.kostitsin@bk.ru
2019-12-15 16:12:07,036 https://sun9-24.userapi.com/c840132/v840132969/40916/Tr3HbZNuvbY.jpg
2019-12-15 16:12:07,319 127.0.0.1 - - [15/Dec/2019 16:12:07] "POST /submit HTTP/1.1" 200 -
2019-12-15 16:19:44,296  * Running on http://127.0.0.1:5000/ (Press CTRL+C to quit)
2019-12-15 16:20:01,522 Поступил запрос на создание задачи, параметры: email = s.kostitsin@bk.ru, url = https://sun9-24.userapi.com/c840132/v840132969/40916/Tr3HbZNuvbY.jpg
2019-12-15 16:20:01,665 127.0.0.1 - - [15/Dec/2019 16:20:01] "POST /submit HTTP/1.1" 200 -
2019-12-15 16:21:16,762 Поступил запрос по задаче с id = 2906f4cb-3852-4b2a-b61c-9f6137e0a606
2019-12-15 16:21:16,764 127.0.0.1 - - [15/Dec/2019 16:21:16] "GET /check?id=2906f4cb-3852-4b2a-b61c-9f6137e0a606 HTTP/1.1" 200 -
